Workbook

Sheet Lega 10
A1: ASTA QUELLI CHE.. LA SCIMMIA DI FANTACALCIO
A2: ALTERATI1926 | D2: DELU TEAM | G2: LE TROFIE 'NFOJATE | J2: MAMBO FC | M2: MANZOTEAM | P2: MOJITO FC MOJITO FC | S2: PANCINO TEAM | V2: PATATINAKOS PATATINAIKOS PATATINAIKOS PATATINAIKOS PATATINAIKOS | Y2: SAMPMANIA SAMPMANIA | AB2: SPACCA CFC
A3: PORTIERI | D3: PORTIERI | G3: PORTIERI | J3: PORTIERI | M3: PORTIERI | P3: PORTIERI | S3: PORTIERI | V3: PORTIERI | Y3: PORTIERI | AB3: PORTIERI
A4: Tatarusanu | B4: =0.5*C4 -> 0 | C4: 0 | D4: Sorrentino | E4: =0.5*F4 -> 6.5 | F4: 13 | G4: Sportiello | H4: =0.5*I4 -> 0.5 | I4: 1 | J4: Consigli | K4: =0.5*L4 -> 0.5 | L4: 1 | M4: Buffon | N4: =0.5*O4 -> 18.5 | O4: 37 | P4: Handanovic | Q4: =0.5*R4 -> 7 | R4: 14 | S4: Viviano | T4: =0.5*U4 -> 1 | U4: 2 | V4: Hart | W4: =0.5*X4 -> 3.5 | X4: 7 | Y4: Donnarumma | Z4: =0.5*AA4 -> 0.5 | AA4: 1 | AB4: Reina | AC4: =0.5*AD4 -> 7.5 | AD4: 15
A5: Lezzerini | B5: =0.5*C5 -> 0 | C5: 0 | D5: Perin | E5: =0.5*F5 -> 3.5 | F5: 7 | G5: Berisha | H5: =0.5*I5 -> 0 | I5: 0 | J5: Szczesny | K5: =0.5*L5 -> 14 | L5: 28 | M5: Neto | N5: =0.5*O5 -> 0 | O5: 0 | P5: Carrizo | Q5: =0.5*R5 -> 0 | R5: 0 | S5: Puggioni | T5: =0.5*U5 -> 0 | U5: 0 | V5: Padelli | W5: =0.5*X5 -> 0 | X5: 0 | Y5: Marchetti | Z5: =0.5*AA5 -> 4 | AA5: 8 | AB5: Sepe | AC5: =0.5*AD5 -> 0 | AD5: 0
A6: Skorupski | B6: =0.5*C6 -> 0.5 | C6: 1 | D6: Lamanna | E6: =0.5*F6 -> 0 | F6: 0 | G6: Karnezis | H6: =0.5*I6 -> 1 | I6: 2 | J6: Alisson | K6: =0.5*L6 -> 0 | L6: 0 | M6: Audero | N6: =0.5*O6 -> 0.5 | O6: 1 | P6: Berni | Q6: =0.5*R6 -> 0.5 | R6: 1 | S6: Tozzo | T6: =0.5*U6 -> 0.5 | U6: 1 | V6: Storari | W6: =0.5*X6 -> 2 | X6: 4 | Y6: Gabriel | Z6: =0.5*AA6 -> 0 | AA6: 0 | AB6: Rafael | AC6: =0.5*AD6 -> 0.5 | AD6: 1
B7: =0.5*C7 -> 0.5 | C7: =SUM(C4:C6) -> 1 | E7: =0.5*F7 -> 10 | F7: =SUM(F4:F6) -> 20 | H7: =0.5*I7 -> 1.5 | I7: =SUM(I4:I6) -> 3 | K7: =0.5*L7 -> 14.5 | L7: =SUM(L4:L6) -> 29 | N7: =0.5*O7 -> 19 | O7: =SUM(O4:O6) -> 38 | Q7: =0.5*R7 -> 7.5 | R7: =SUM(R4:R6) -> 15 | T7: =0.5*U7 -> 1.5 | U7: =SUM(U4:U6) -> 3 | W7: =0.5*X7 -> 5.5 | X7: =SUM(X4:X6) -> 11 | Z7: =0.5*AA7 -> 4.5 | AA7: =SUM(AA4:AA6) -> 9 | AC7: =0.5*AD7 -> 8 | AD7: =SUM(AD4:AD6) -> 16
A8: DIFENSORI | D8: DIFENSORI | G8: DIFENSORI | J8: DIFENSORI | M8: DIFENSORI | P8: DIFENSORI | S8: DIFENSORI | V8: DIFENSORI | Y8: DIFENSORI | AB8: DIFENSORI
A9: Hysaj | B9: =0.5*C9 -> 3.5 | C9: 7 | D9: Ansaldi | E9: =0.5*F9 -> 0.5 | F9: 1 | G9: Alex Sandro | H9: =0.5*I9 -> 6 | I9: 12 | J9: Bruno Peres | K9: =0.5*L9 -> 5 | L9: 10 | M9: De Silvestri | N9: =0.5*O9 -> 2 | O9: 4 | P9: Bonucci | Q9: =0.5*R9 -> 4 | R9: 8 | S9: Martella | T9: =0.5*U9 -> 3.5 | U9: 7 | V9: Widmer | W9: =0.5*X9 -> 2 | X9: 4 | Y9: Cannavaro | Z9: =0.5*AA9 -> 1 | AA9: 2 | AB9: Barzagli | AC9: =0.5*AD9 -> 2.5 | AD9: 5
A10: Rodriguez | B10: =0.5*C10 -> 4.5 | C10: 9 | D10: Florenzi | E10: =0.5*F10 -> 12 | F10: 24 | G10: Basta | H10: =0.5*I10 -> 2 | I10: 4 | J10: Miranda | K10: =0.5*L10 -> 4.5 | L10: 9 | M10: Rispoli | N10: =0.5*O10 -> 1.5 | O10: 3 | P10: Astori | Q10: =0.5*R10 -> 2 | R10: 4 | S10: Dani Alves | T10: =0.5*U10 -> 7 | U10: 14 | V10: Chiellini | W10: =0.5*X10 -> 2.5 | X10: 5 | Y10: Murillo | Z10: =0.5*AA10 -> 3 | AA10: 6 | AB10: Koulibaly | AC10: =0.5*AD10 -> 5.5 | AD10: 11
A11: De Vrij | B11: =0.5*C11 -> 3 | C11: 6 | D11: Molinaro | E11: =0.5*F11 -> 1 | F11: 2 | G11: Isla | H11: =0.5*I11 -> 4 | I11: 8 | J11: Edenilson | K11: =0.5*L11 -> 1 | L11: 2 | M11: Bastos | N11: =0.5*O11 -> 3.5 | O11: 7 | P11: Gastaldello | Q11: =0.5*R11 -> 2.5 | R11: 5 | S11: Ghoulam | T11: =0.5*U11 -> 3 | U11: 6 | V11: Dramè | W11: =0.5*X11 -> 1 | X11: 2 | Y11: Regini | Z11: =0.5*AA11 -> 0.5 | AA11: 1 | AB11: Vermaelen | AC11: =0.5*AD11 -> 2 | AD11: 4
A12: Abate | B12: =0.5*C12 -> 1.5 | C12: 3 | D12: Masina | E12: =0.5*F12 -> 2.5 | F12: 5 | G12: Benatia | H12: =0.5*I12 -> 4 | I12: 8 | J12: Pasqual | K12: =0.5*L12 -> 3 | L12: 6 | M12: Krafth | N12: =0.5*O12 -> 1.5 | O12: 3 | P12: Manolas | Q12: =0.5*R12 -> 3.5 | R12: 7 | S12: Zukanovic | T12: =0.5*U12 -> 3 | U12: 6 | V12: Izzo | W12: =0.5*X12 -> 1.5 | X12: 3 | Y12: Romagnoli | Z12: =0.5*AA12 -> 2.5 | AA12: 5 | AB12: Zampano | AC12: =0.5*AD12 -> 2 | AD12: 4
A13: D'Ambrosio | B13: =0.5*C13 -> 0.5 | C13: 1 | D13: Silvestre | E13: =0.5*F13 -> 2 | F13: 4 | G13: Conti | H13: =0.5*I13 -> 2 | I13: 4 | J13: Bruno Alves | K13: =0.5*L13 -> 1 | L13: 2 | M13: Alesami | N13: =0.5*O13 -> 0.5 | O13: 1 | P13: De Sciglio | Q13: =0.5*R13 -> 2 | R13: 4 | S13: Maksimovic | T13: =0.5*U13 -> 3 | U13: 6 | V13: Hoedt | W13: =0.5*X13 -> 1.5 | X13: 3 | Y13: Zappacosta | Z13: =0.5*AA13 -> 0.5 | AA13: 1 | AB13: Danilo | AC13: =0.5*AD13 -> 1.5 | AD13: 3
A14: Castan | B14: =0.5*C14 -> 0.5 | C14: 1 | D14: Pavlovic | E14: =0.5*F14 -> 1 | F14: 2 | G14: Evra | H14: =0.5*I14 -> 2 | I14: 4 | J14: Gobbi | K14: =0.5*L14 -> 0.5 | L14: 1 | M14: Peluso | N14: =0.5*O14 -> 1.5 | O14: 3 | P14: Acerbi | Q14: =0.5*R14 -> 5 | R14: 10 | S14: Albiol | T14: =0.5*U14 -> 3.5 | U14: 7 | V14: Cacciatore | W14: =0.5*X14 -> 2.5 | X14: 5 | Y14: Mario Rui | Z14: =0.5*AA14 -> 0.5 | AA14: 1 | AB14: Ferrari G | AC14: =0.5*AD14 -> 1.5 | AD14: 3
A15: Goldaniga | B15: =0.5*C15 -> 0.5 | C15: 1 | D15: Heurtaux | E15: =0.5*F15 -> 0.5 | F15: 1 | G15: Lukaku | H15: =0.5*I15 -> 0.5 | I15: 1 | J15: Biraghi | K15: =0.5*L15 -> 0.5 | L15: 1 | M15: Costa | N15: =0.5*O15 -> 0.5 | O15: 1 | P15: Antonelli | Q15: =0.5*R15 -> 2.5 | R15: 5 | S15: Lichsteiner | T15: =0.5*U15 -> 1 | U15: 2 | V15: Gentiletti | W15: =0.5*X15 -> 0.5 | X15: 1 | Y15: Moretti | Z15: =0.5*AA15 -> 0.5 | AA15: 1 | AB15: Burdisso | AC15: =0.5*AD15 -> 1 | AD15: 2
A16: Laurini | B16: =0.5*C16 -> 0.5 | C16: 1 | D16: Dodò | E16: =0.5*F16 -> 0.5 | F16: 1 | G16: Oliveira | H16: =0.5*I16 -> 0.5 | I16: 1 | J16: Rudiger | K16: =0.5*L16 -> 0.5 | L16: 1 | M16: Rosi | N16: =0.5*O16 -> 0.5 | O16: 1 | P16: Calabria | Q16: =0.5*R16 -> 0.5 | R16: 1 | S16: Ceccherini | T16: =0.5*U16 -> 0.5 | U16: 1 | V16: Juan Jesus | W16: =0.5*X16 -> 0.5 | X16: 1 | Y16: Zapata | Z16: =0.5*AA16 -> 0.5 | AA16: 1 | AB16: Orban | AC16: =0.5*AD16 -> 0.5 | AD16: 1
B17: =0.5*C17 -> 14.5 | C17: =SUM(C9:C16) -> 29 | E17: =0.5*F17 -> 20 | F17: =SUM(F9:F16) -> 40 | H17: =0.5*I17 -> 21 | I17: =SUM(I9:I16) -> 42 | K17: =0.5*L17 -> 16 | L17: =SUM(L9:L16) -> 32 | N17: =0.5*O17 -> 11.5 | O17: =SUM(O9:O16) -> 23 | Q17: =0.5*R17 -> 22 | R17: =SUM(R9:R16) -> 44 | T17: =0.5*U17 -> 24.5 | U17: =SUM(U9:U16) -> 49 | W17: =0.5*X17 -> 12 | X17: =SUM(X9:X16) -> 24 | Z17: =0.5*AA17 -> 9 | AA17: =SUM(AA9:AA16) -> 18 | AC17: =0.5*AD17 -> 16.5 | AD17: =SUM(AD9:AD16) -> 33
A18: CENTROCAMPO | D18: CENTROCAMPO | G18: CENTROCAMPO | J18: CENTROCAMPO | M18: CENTROCAMPO | P18: CENTROCAMPO | S18: CENTROCAMPO | V18: CENTROCAMPO | Y18: CENTROCAMPO | AB18: CENTROCAMPO
A19: Mertens | B19: =0.5*C19 -> 7.5 | C19: 15 | D19: Ljaic | E19: =0.5*F19 -> 1.5 | F19: 3 | G19: Gomez | H19: =0.5*I19 -> 6.5 | I19: 13 | J19: Paredes | K19: =0.5*L19 -> 0.5 | L19: 1 | M19: Khedira | N19: =0.5*O19 -> 0.5 | O19: 1 | P19: Perotti | Q19: =0.5*R19 -> 9.5 | R19: 19 | S19: Saponara | T19: =0.5*U19 -> 2 | U19: 4 | V19: Hamsik | W19: =0.5*X19 -> 20 | X19: 40 | Y19: Perisic | Z19: =0.5*AA19 -> 9 | AA19: 18 | AB19: Suso | AC19: =0.5*AD19 -> 5.5 | AD19: 11
A20: Bernardeschi | B20: =0.5*C20 -> 7.5 | C20: 15 | D20: D'Alessandro | E20: =0.5*F20 -> 5 | F20: 10 | G20: Borja Valero | H20: =0.5*I20 -> 14.5 | I20: 29 | J20: Birsa | K20: =0.5*L20 -> 8.5 | L20: 17 | M20: Pjanic | N20: =0.5*O20 -> 19 | O20: 38 | P20: Strootman | Q20: =0.5*R20 -> 11 | R20: 22 | S20: Rincon | T20: =0.5*U20 -> 4.5 | U20: 9 | V20: Candreva | W20: =0.5*X20 -> 20 | X20: 40 | Y20: Duncan | Z20: =0.5*AA20 -> 1.5 | AA20: 3 | AB20: Banega | AC20: =0.5*AD20 -> 5.5 | AD20: 11
A21: Felipe Anderson | B21: =0.5*C21 -> 17.5 | C21: 35 | D21: Nainggolan | E21: =0.5*F21 -> 18 | F21: 36 | G21: Lulic | H21: =0.5*I21 -> 3.5 | I21: 7 | J21: Bonaventura | K21: =0.5*L21 -> 16 | L21: 32 | M21: Linetty | N21: =0.5*O21 -> 2 | O21: 4 | P21: Joao Mario | Q21: =0.5*R21 -> 8 | R21: 16 | S21: Kessie | T21: =0.5*U21 -> 5 | U21: 10 | V21: Praet | W21: =0.5*X21 -> 9 | X21: 18 | Y21: Parolo | Z21: =0.5*AA21 -> 7 | AA21: 14 | AB21: Sosa | AC21: =0.5*AD21 -> 0.5 | AD21: 1
A22: Fofana | B22: =0.5*C22 -> 0.5 | C22: 1 | D22: Padoin | E22: =0.5*F22 -> 1 | F22: 2 | G22: Krejcy | H22: =0.5*I22 -> 3 | I22: 6 | J22: Allan | K22: =0.5*L22 -> 4 | L22: 8 | M22: Jorginho | N22: =0.5*O22 -> 4.5 | O22: 9 | P22: Fernandez | Q22: =0.5*R22 -> 5 | R22: 10 | S22: Kums | T22: =0.5*U22 -> 2.5 | U22: 5 | V22: Verdi | W22: =0.5*X22 -> 1.5 | X22: 3 | Y22: De Rossi | Z22: =0.5*AA22 -> 2.5 | AA22: 5 | AB22: Laxalt | AC22: =0.5*AD22 -> 3.5 | AD22: 7
A23: Kurtic | B23: =0.5*C23 -> 0.5 | C23: 1 | D23: Sala | E23: =0.5*F23 -> 0.5 | F23: 1 | G23: De Paul | H23: =0.5*I23 -> 1.5 | I23: 3 | J23: Torreira | K23: =0.5*L23 -> 1 | L23: 2 | M23: Verre | N23: =0.5*O23 -> 4 | O23: 8 | P23: Benali | Q23: =0.5*R23 -> 4 | R23: 8 | S23: Diamanti | T23: =0.5*U23 -> 4 | U23: 8 | V23: Lemina | W23: =0.5*X23 -> 2.5 | X23: 5 | Y23: Kongdombia | Z23: =0.5*AA23 -> 0.5 | AA23: 1 | AB23: Veloso | AC23: =0.5*AD23 -> 1 | AD23: 2
A24: Tonev | B24: =0.5*C24 -> 0.5 | C24: 1 | D24: Tello | E24: =0.5*F24 -> 2.5 | F24: 5 | G24: Cuadrado | H24: =0.5*I24 -> 5 | I24: 10 | J24: Memushaj | K24: =0.5*L24 -> 4 | L24: 8 | M24: Capezzi | N24: =0.5*O24 -> 2.5 | O24: 5 | P24: Baselli | Q24: =0.5*R24 -> 6.5 | R24: 13 | S24: Biglia | T24: =0.5*U24 -> 4.5 | U24: 9 | V24: Mounier | W24: =0.5*X24 -> 0.5 | X24: 1 | Y24: Brozovic | Z24: =0.5*AA24 -> 0.5 | AA24: 1 | AB24: Magnanelli | AC24: =0.5*AD24 -> 1 | AD24: 2
A25: Montolivo | B25: =0.5*C25 -> 0.5 | C25: 1 | D25: Joao Pedro | E25: =0.5*F25 -> 7.5 | F25: 15 | G25: Rog | H25: =0.5*I25 -> 0.5 | I25: 1 | J25: Vecino | K25: =0.5*L25 -> 1.5 | L25: 3 | M25: Rigoni | N25: =0.5*O25 -> 1 | O25: 2 | P25: Alvarez | Q25: =0.5*R25 -> 3 | R25: 6 | S25: Marchisio | T25: =0.5*U25 -> 2.5 | U25: 5 | V25: Valdifiori | W25: =0.5*X25 -> 0.5 | X25: 1 | Y25: Missiroli | Z25: =0.5*AA25 -> 1.5 | AA25: 3 | AB25: Iago Falque | AC25: =0.5*AD25 -> 8 | AD25: 16
A26: Benassi | B26: =0.5*C26 -> 0.5 | C26: 1 | D26: Asamoah | E26: =0.5*F26 -> 1 | F26: 2 | G26: Ntcham | H26: =0.5*I26 -> 0.5 | I26: 1 | J26: Ionita | K26: =0.5*L26 -> 0.5 | L26: 1 | M26: Hetemaj | N26: =0.5*O26 -> 0.5 | O26: 1 | P26: Diawara | Q26: =0.5*R26 -> 1.5 | R26: 3 | S26: Di Gennaro | T26: =0.5*U26 -> 3 | U26: 6 | V26: Medel | W26: =0.5*X26 -> 0.5 | X26: 1 | Y26: Politano | Z26: =0.5*AA26 -> 2.5 | AA26: 5 | AB26: Pasalic | AC26: =0.5*AD26 -> 0.5 | AD26: 1
B27: =0.5*C27 -> 35 | C27: =SUM(C19:C26) -> 70 | E27: =0.5*F27 -> 37 | F27: =SUM(F19:F26) -> 74 | H27: =0.5*I27 -> 35 | I27: =SUM(I19:I26) -> 70 | K27: =0.5*L27 -> 36 | L27: =SUM(L19:L26) -> 72 | N27: =0.5*O27 -> 34 | O27: =SUM(O19:O26) -> 68 | Q27: =0.5*R27 -> 48.5 | R27: =SUM(R19:R26) -> 97 | T27: =0.5*U27 -> 28 | U27: =SUM(U19:U26) -> 56 | W27: =0.5*X27 -> 54.5 | X27: =SUM(X19:X26) -> 109 | Z27: =0.5*AA27 -> 25 | AA27: =SUM(AA19:AA26) -> 50 | AC27: =0.5*AD27 -> 25.5 | AD27: =SUM(AD19:AD26) -> 51
A28: ATTACCANTI | D28: ATTACCANTI | G28: ATTACCANTI | J28: ATTACCANTI | M28: ATTACCANTI | P28: ATTACCANTI | S28: ATTACCANTI | V28: ATTACCANTI | Y28: ATTACCANTI | AB28: ATTACCANTI
A29: Bacca | B29: =0.5*C29 -> 45.5 | C29: 91 | D29: Icardi | E29: =0.5*F29 -> 55.5 | F29: 111 | G29: Belotti | H29: =0.5*I29 -> 9 | I29: 18 | J29: Berardi | K29: =0.5*L29 -> 4 | L29: 8 | M29: Immobile | N29: =0.5*O29 -> 16.5 | O29: 33 | P29: Dybala | Q29: =0.5*R29 -> 2.5 | R29: 5 | S29: Milik | T29: =0.5*U29 -> 60.5 | U29: 121 | V29: Callejon | W29: =0.5*X29 -> 34.5 | X29: 69 | Y29: Higuain | Z29: =0.5*AA29 -> 72 | AA29: 144 | AB29: Pavoletti | AC29: =0.5*AD29 -> 60 | AD29: 120
A30: Dzeko | B30: =0.5*C30 -> 35 | C30: 70 | D30: Quagliarella | E30: =0.5*F30 -> 21.5 | F30: 43 | G30: Pjaca | H30: =0.5*I30 -> 15 | I30: 30 | J30: Kalinic | K30: =0.5*L30 -> 41.5 | L30: 83 | M30: Caprari | N30: =0.5*O30 -> 6 | O30: 12 | P30: Niang | Q30: =0.5*R30 -> 21.5 | R30: 43 | S30: Insigne | T30: =0.5*U30 -> 30 | U30: 60 | V30: Muriel | W30: =0.5*X30 -> 31.5 | X30: 63 | Y30: Mandzukic | Z30: =0.5*AA30 -> 32 | AA30: 64 | AB30: Borriello | AC30: =0.5*AD30 -> 16.5 | AD30: 33
A31: Zarate | B31: =0.5*C31 -> 3 | C31: 6 | D31: Maccarone | E31: =0.5*F31 -> 5.5 | F31: 11 | G31: Ilicic | H31: =0.5*I31 -> 31.5 | I31: 63 | J31: Paloschi | K31: =0.5*L31 -> 20 | L31: 40 | M31: Salah | N31: =0.5*O31 -> 45 | O31: 90 | P31: El Sharaawy | Q31: =0.5*R31 -> 22 | R31: 44 | S31: Gilardino | T31: =0.5*U31 -> 4 | U31: 8 | V31: Inglese | W31: =0.5*X31 -> 2 | X31: 4 | Y31: Zapata | Z31: =0.5*AA31 -> 11.5 | AA31: 23 | AB31: Ocampos | AC31: =0.5*AD31 -> 7 | AD31: 14
A32: Defrel | B32: =0.5*C32 -> 12.5 | C32: 25 | D32: Farias | E32: =0.5*F32 -> 0.5 | F32: 1 | G32: Gabbiadini | H32: =0.5*I32 -> 17.5 | I32: 35 | J32: Matri | K32: =0.5*L32 -> 12.5 | L32: 25 | M32: Palladino | N32: =0.5*O32 -> 2.5 | O32: 5 | P32: Eder | Q32: =0.5*R32 -> 11.5 | R32: 23 | S32: Keita | T32: =0.5*U32 -> 5.5 | U32: 11 | V32: Meggiorini | W32: =0.5*X32 -> 4 | X32: 8 | Y32: Jovetic | Z32: =0.5*AA32 -> 0.5 | AA32: 1 | AB32: Simeone | AC32: =0.5*AD32 -> 0.5 | AD32: 1
A33: Nestorovski | B33: =0.5*C33 -> 0.5 | C33: 1 | D33: Manaj | E33: =0.5*F33 -> 0.5 | F33: 1 | G33: Gabigol | H33: =0.5*I33 -> 11.5 | I33: 23 | J33: Pucciarelli | K33: =0.5*L33 -> 5 | L33: 10 | M33: Destro | N33: =0.5*O33 -> 18 | O33: 36 | P33: Sau | Q33: =0.5*R33 -> 8.5 | R33: 17 | S33: Sadiq | T33: =0.5*U33 -> 0.5 | U33: 1 | V33: Budimir | W33: =0.5*X33 -> 5 | X33: 10 | Y33: Perica | Z33: =0.5*AA33 -> 0.5 | AA33: 1 | AB33: Thereau | AC33: =0.5*AD33 -> 6.5 | AD33: 13
A34: Babacar | B34: =0.5*C34 -> 0.5 | C34: 1 | D34: Schick | E34: =0.5*F34 -> 0.5 | F34: 1 | G34: Boyè | H34: =0.5*I34 -> 0.5 | I34: 1 | J34: Trotta | K34: =0.5*L34 -> 0.5 | L34: 1 | M34: Penaranda | N34: =0.5*O34 -> 1.5 | O34: 3 | P34: Lapadula | Q34: =0.5*R34 -> 2.5 | R34: 5 | S34: Ragusa | T34: =0.5*U34 -> 0.5 | U34: 1 | V34: Falcinelli | W34: =0.5*X34 -> 1.5 | X34: 3 | Y34: Martinez | Z34: =0.5*AA34 -> 0.5 | AA34: 1 | AB34: Luis Alberto | AC34: =0.5*AD34 -> 3.5 | AD34: 7
B35: =0.5*C35 -> 97 | C35: =SUM(C29:C34) -> 194 | E35: =0.5*F35 -> 84 | F35: =SUM(F29:F34) -> 168 | H35: =0.5*I35 -> 85 | I35: =SUM(I29:I34) -> 170 | K35: =0.5*L35 -> 83.5 | L35: =SUM(L29:L34) -> 167 | N35: =0.5*O35 -> 89.5 | O35: =SUM(O29:O34) -> 179 | Q35: =0.5*R35 -> 68.5 | R35: =SUM(R29:R34) -> 137 | T35: =0.5*U35 -> 101 | U35: =SUM(U29:U34) -> 202 | W35: =0.5*X35 -> 78.5 | X35: =SUM(X29:X34) -> 157 | Z35: =0.5*AA35 -> 117 | AA35: =SUM(AA29:AA34) -> 234 | AC35: =0.5*AD35 -> 94 | AD35: =SUM(AD29:AD34) -> 188
A36: RESTANTI | B36: =0.5*C36 -> 149.5 | C36: =$C40-(C7+A17+A27+A35)+C38 -> 299 | D36: RESTANTI | F36: =$F40-(F7+D17+D27+D35)+F38 -> 291 | G36: RESTANTI | I36: =$I40-(I7+G17+G27+G35)+I38 -> 299 | J36: RESTANTI | L36: =$L40-(L7+J17+J27+J35)+L38 -> 272 | M36: RESTANTI | O36: =$O40-(O7+M17+M27+M35)+O38 -> 275 | P36: RESTANTI | R36: =$R40-(R7+P17+P27+P35)+R38 -> 296 | S36: RESTANTI | U36: =$U40-(U7+S17+S27+S35)+U38 -> 307 | V36: RESTANTI | X36: =$X40-(X7+V17+V27+V35)+X38 -> 290 | Y36: RESTANTI | AA36: =$AA40-(AA7+Y17+Y27+Y35)+AA38 -> 302 | AB36: RESTANTI | AD36: =$AD40-(AD7+AB17+AB27+AB35)+AD38 -> 302
A38: Crediti Buste | D38: Crediti Buste | G38: Crediti Buste | J38: Crediti Buste | M38: Crediti Buste | P38: Crediti Buste | S38: Crediti Buste | V38: Crediti Buste | Y38: Crediti Buste | AB38: Crediti Buste
A40: BUDGET | B40: =0.5*C40 -> 150 | C40: 300 | D40: BUDGET | F40: 311 | G40: BUDGET | I40: 302 | J40: BUDGET | L40: 301 | M40: BUDGET | O40: 313 | P40: BUDGET | R40: 311 | S40: BUDGET | U40: 310 | V40: BUDGET | X40: 301 | Y40: BUDGET | AA40: 311 | AB40: BUDGET | AD40: 318

Sheet Panchine
A1: Giornata | B1: STRAW DOGS | D1: DELU TEAM | F1: TROFIE 'NFOIATE | H1: MAMBO FC | J1: MANZOTEAM | L1: MOJITO FC | N1: RCD SUERTE | P1: PATATINAIKOS | R1: SAMPMANIA | T1: SPACCA CFC
B2: Bonus/Malus | C2: Totale | D2: Bonus/Malus | E2: Totale | F2: Bonus/Malus | G2: Totale | H2: Bonus/Malus | I2: Totale | J2: Bonus/Malus | K2: Totale | L2: Bonus/Malus | M2: Totale | N2: Bonus/Malus | O2: Totale | P2: Bonus/Malus | Q2: Totale | R2: Bonus/Malus | S2: Totale | T2: Bonus/Malus | U2: Totale
A3: 1 | B3: 1 | C3: 31.5 | D3: 6.5 | E3: 49.5 | F3: 0.5 | G3: 46 | H3: -0.5 | I3: 46.5 | J3: -3 | K3: 26.5 | L3: 0 | M3: 17 | N3: 0.5 | O3: 50.5 | P3: 0 | Q3: 55 | R3: -3 | S3: 20 | T3: 5 | U3: 84
A4: 2 | B4: -0.5 | C4: 24 | D4: -0.5 | E4: 33.5 | F4: -1 | G4: 40.5 | H4: 6 | I4: 47 | J4: -3 | K4: 25.5 | L4: 0 | M4: 28.5 | N4: 2 | O4: 50.5 | P4: -2.5 | Q4: 58.5 | R4: 0 | S4: 10.5 | T4: 6.5 | U4: 104.5
A5: 3 | B5: 0.5 | C5: 49 | D5: 0 | E5: 11.5 | F5: 1.5 | G5: 67.5 | H5: 0 | I5: 49 | J5: 1 | K5: 18.5 | L5: 0 | M5: 17 | N5: 4 | O5: 52.5 | P5: 3 | Q5: 51.5 | R5: 0 | S5: 5.5 | T5: -1 | U5: 75
A6: 4 | B6: -1 | C6: 64 | D6: 0.5 | E6: 61 | F6: -2.5 | G6: 38.5 | H6: 0.5 | I6: 56 | J6: -0.5 | K6: 23.5 | L6: -1 | M6: 47.5 | N6: -1.5 | O6: 59 | P6: 0 | Q6: 52 | R6: 0 | S6: 36.5 | T6: 3 | U6: 58.5
A7: 5 | B7: 3 | C7: 52 | D7: 0 | E7: 34.5 | F7: 4 | G7: 73 | H7: -1 | I7: 28.5 | J7: 0 | K7: 16.5 | L7: 1.5 | M7: 48 | N7: -2 | O7: 55.5 | P7: 1 | Q7: 39 | R7: -2 | S7: 38.5 | T7: 0 | U7: 85.5
A8: 6 | B8: 5.5 | C8: 53.5 | D8: 6 | E8: 48.5 | F8: 0 | G8: 57 | H8: -0.5 | I8: 28 | J8: 0 | K8: 11.5 | L8: 0 | M8: 58.5 | N8: 9 | O8: 53.5 | P8: -1 | Q8: 58 | R8: 0 | S8: 36 | T8: 14 | U8: 100
A9: 7 | B9: -0.5 | C9: 47.5 | D9: -0.5 | E9: 57.5 | F9: 4.5 | G9: 60 | H9: 5 | I9: 30 | J9: -0.5 | K9: 11.5 | L9: 3.5 | M9: 57 | N9: -1 | O9: 35.5 | P9: 0.5 | Q9: 59.5 | R9: -0.5 | S9: 40 | T9: 4 | U9: 97.5
A10: 8 | B10: 0 | C10: 49 | D10: 3.5 | E10: 68 | F10: 4 | G10: 54.5 | H10: 10.5 | I10: 37.5 | J10: 0 | K10: 41 | L10: 0.5 | M10: 67.5 | N10: 0 | O10: 46.5 | P10: -2.5 | Q10: 65 | R10: 7 | S10: 35 | T10: 8 | U10: 88
A11: 9 | B11: 4 | C11: 61 | D11: 4.5 | E11: 54.5 | F11: -1 | G11: 23 | H11: 0 | I11: 30 | J11: 7.5 | K11: 57.5 | L11: 8.5 | M11: 73.5 | N11: 1 | O11: 30.5 | P11: 6.5 | Q11: 79.5 | R11: 3 | S11: 39.5 | T11: -0.5 | U11: 56.5
A12: 10 | B12: 0.5 | C12: 61.5 | D12: 3.5 | E12: 57.5 | F12: -2.5 | G12: 26.5 | H12: 2.5 | I12: 53 | J12: 4 | K12: 39.5 | L12: 3.5 | M12: 62.5 | N12: 3.5 | O12: 37.5 | P12: 1 | Q12: 61 | R12: -1 | S12: 23 | T12: 0 | U12: 75
A13: 11 | B13: 0 | C13: 54 | D13: 1 | E13: 49 | F13: 1 | G13: 42 | H13: 0 | I13: 40 | J13: 7 | K13: 56 | L13: 13.5 | M13: 74 | N13: 0 | O13: 27.5 | P13: 5 | Q13: 58.5 | R13: 0.5 | S13: 19.5 | T13: 4.5 | U13: 83
A14: 12 | B14: -0.5 | C14: 51.5 | D14: 1 | E14: 52.5 | F14: -1 | G14: 36 | H14: 0 | I14: 17.5 | J14: 2.5 | K14: 46 | L14: 18 | M14: 85.5 | N14: 3.5 | O14: 29 | P14: -2 | Q14: 39.5 | R14: 0 | S14: 23.5 | T14: 4 | U14: 95.5
... A37: 35 | B37: -1.5 | C37: 56.5 | D37: 1.5 | E37: 70 | F37: 7.5 | G37: 77.5 | H37: 0 | I37: 18 | J37: 3 | K37: 34 | L37: 0 | M37: 33.5 | N37: 8.5 | O37: 58 | P37: -2 | Q37: 40 | R37: -0.5 | S37: 60 | T37: 1.5 | U37: 56
A38: 36
A39: TOTALE | B39: =SUM(B3:B38) -> 39.5 | C39: =SUM(C3:C38) -> 1748 | D39: =SUM(D3:D38) -> 44.5 | E39: =SUM(E3:E38) -> 1976 | F39: =SUM(F3:F38) -> 55.5 | G39: =SUM(G3:G38) -> 2210.5 | H39: =SUM(H3:H38) -> 59.5 | I39: =SUM(I3:I38) -> 1296.5 | ... U39: =SUM(U3:U38) -> 2805.5
A40: MEDIA | B40: =AVERAGE(B3:B38) -> 1.1285714 | C40: =AVERAGE(C3:C38) -> 49.942857 | D40: =AVERAGE(D3:D38) -> 1.2714286 | E40: =AVERAGE(E3:E38) -> 56.457143 | F40: =AVERAGE(F3:F38) -> 1.5857143 | G40: =AVERAGE(G3:G38) -> 63.157143 | H40: =AVERAGE(H3:H38) -> 1.7 | I40: =AVERAGE(I3:I38) -> 37.042857 | ... U40: =AVERAGE(U3:U38) -> 80.157143
A42: Non Sfruttati | B42: Gol | C42: Assist | D42: Gol | E42: Assist | F42: Gol | G42: Assist | H42: Gol | I42: Assist | J42: Gol | K42: Assist | L42: Gol | M42: Assist | N42: Gol | O42: Assist | P42: Gol | Q42: Assist | R42: Gol | S42: Assist | T42: Gol | U42: Assist
B43: 9 | C43: 13 | D43: 16 | E43: 18 | F43: 34 | G43: 15 | H43: 16 | I43: 9 | J43: 19 | K43: 3 | L43: 33 | M43: 15 | N43: 20 | O43: 14 | P43: 13 | Q43: 16 | R43: 9 | S43: 7 | T43: 36 | U43: 28
A44: % sul Totale | B44: =B43/(B43+'Bonus-Malus'!B10) -> 0.20930233 | C44: =C43/(C43+'Bonus-Malus'!I10) -> 0.37142857 | D44: =D43/(D43+'Bonus-Malus'!B2) -> 0.22535211 | E44: =E43/(E43+'Bonus-Malus'!I2) -> 0.38297872 | F44: =F43/(F43+'Bonus-Malus'!B11) -> 0.4 | G44: =G43/(G43+'Bonus-Malus'!I11) -> 0.35714286 | H44: =H43/(H43+'Bonus-Malus'!B3) -> 0.25 | I44: =I43/(I43+'Bonus-Malus'!I3) -> 0.32142857 | J44: =J43/(J43+'Bonus-Malus'!B4) -> 0.27142857 | K44: =K43/(K43+'Bonus-Malus'!I4) -> 0.068181818 | L44: =L43/(L43+'Bonus-Malus'!B5) -> 0.49253731 | M44: =M43/(M43+'Bonus-Malus'!I5) -> 0.41666667 | N44: =N43/(N43+'Bonus-Malus'!B7) -> 0.29850746 | O44: =O43/(O43+'Bonus-Malus'!I7) -> 0.3255814 | P44: =P43/(P43+'Bonus-Malus'!B6) -> 0.22033898 | Q44: =Q43/(Q43+'Bonus-Malus'!I6) -> 0.4 | R44: =R43/(R43+'Bonus-Malus'!B8) -> 0.17307692 | S44: =S43/(S43+'Bonus-Malus'!I8) -> 0.23333333 | T44: =T43/(T43+'Bonus-Malus'!B9) -> 0.4137931 | U44: =U43/(U43+'Bonus-Malus'!I9) -> 0.47457627

Sheet FantaCulo
B1: STRAW DOGS | F1: DELU TEAM | J1: TROFIE 'NFOIATE | N1: MAMBO FC | R1: MANZOTEAM | V1: MOJITO FC | Z1: RCD SUERTE | AD1: PATATINAIKOS | AH1: SAMPMANIA | AL1: SPACCA CFC
B2: V | C2: P | D2: S | E2: Pesato | F2: V | G2: P | H2: S | I2: Pesato | J2: V | K2: P | L2: S | M2: Pesato | N2: V | O2: P | P2: S | Q2: Pesato | R2: V | S2: P | T2: S | U2: Pesato | V2: V | W2: P | X2: S | Y2: Pesato | Z2: V | AA2: P | AB2: S | AC2: Pesato | AD2: V | AE2: P | AF2: S | AG2: Pesato | AH2: V | AI2: P | AJ2: S | AK2: Pesato | AL2: V | AM2: P | AN2: S | AO2: Pesato
A3: 1 | B3: 66.66 | C3: 22.22 | D3: 11.12 | E3: =Punteggio!C3 - (3*FantaCulo!B3/100) + IF(Punteggio!C3=1,(FantaCulo!D3/100)-1, 0) - IF(Punteggio!C3=0,(FantaCulo!C3/100), 0) -> 1.0002 | F3: 22.22 | G3: 22.22 | H3: 55.56 | I3: =Punteggio!E3 - (3*FantaCulo!F3/100) + IF(Punteggio!E3=1,(FantaCulo!H3/100)-1, 0) - IF(Punteggio!E3=0,(FantaCulo!G3/100), 0) -> -0.111 | J3: 22.22 | K3: 22.22 | L3: 55.56 | M3: =Punteggio!G3 - (3*FantaCulo!J3/100) + IF(Punteggio!G3=1,(FantaCulo!L3/100)-1, 0) - IF(Punteggio!G3=0,(FantaCulo!K3/100), 0) -> -0.111 | N3: 66.66 | O3: 22.22 | P3: 11.12 | Q3: =Punteggio!I3 - (3*FantaCulo!N3/100) + IF(Punteggio!I3=1,(FantaCulo!P3/100)-1, 0) - IF(Punteggio!I3=0,(FantaCulo!O3/100), 0) -> 1.0002 | R3: 22.22 | S3: 22.22 | T3: 55.56 | U3: =Punteggio!K3 - (3*FantaCulo!R3/100) + IF(Punteggio!K3=1,(FantaCulo!T3/100)-1, 0) - IF(Punteggio!K3=0,(FantaCulo!S3/100), 0) -> -0.8888 | V3: 55.55 | W3: 0 | X3: 44.45 | Y3: =Punteggio!M3 - (3*FantaCulo!V3/100) + IF(Punteggio!M3=1,(FantaCulo!X3/100)-1, 0) - IF(Punteggio!M3=0,(FantaCulo!W3/100), 0) -> -1.6665 | Z3: 0 | AA3: 11.11 | AB3: 88.89 | AC3: =Punteggio!O3 - (3*FantaCulo!Z3/100) + IF(Punteggio!O3=1,(FantaCulo!AB3/100)-1, 0) - IF(Punteggio!O3=0,(FantaCulo!AA3/100), 0) -> -0.1111 | AD3: 0 | AE3: 11.11 | AF3: 88.89 | AG3: =Punteggio!Q3 - (3*FantaCulo!AD3/100) + IF(Punteggio!Q3=1,(FantaCulo!AF3/100)-1, 0) - IF(Punteggio!Q3=0,(FantaCulo!AE3/100), 0) -> -0.1111 | AH3: 100 | AI3: 0 | AJ3: 0 | AK3: =Punteggio!S3 - (3*FantaCulo!AH3/100) + IF(Punteggio!S3=1,(FantaCulo!AJ3/100)-1, 0) - IF(Punteggio!S3=0,(FantaCulo!AI3/100), 0) -> 0 | AL3: 66.66 | AM3: 22.22 | AN3: 11.12 | AO3: =Punteggio!U3 - (3*FantaCulo!AL3/100) + IF(Punteggio!U3=1,(FantaCulo!AN3/100)-1, 0) - IF(Punteggio!U3=0,(FantaCulo!AM3/100), 0) -> 1.0002
A4: 2 | B4: 33.33 | C4: 44.44 | D4: 22.23 | E4: =Punteggio!C4 - (3*FantaCulo!B4/100) + IF(Punteggio!C4=1,(FantaCulo!D4/100)-1, 0) - IF(Punteggio!C4=0,(FantaCulo!C4/100), 0) -> -0.7776 | F4: 33.33 | G4: 44.44 | H4: 22.23 | I4: =Punteggio!E4 - (3*FantaCulo!F4/100) + IF(Punteggio!E4=1,(FantaCulo!H4/100)-1, 0) - IF(Punteggio!E4=0,(FantaCulo!G4/100), 0) -> -0.7776 | J4: 100 | K4: 0 | L4: 0 | M4: =Punteggio!G4 - (3*FantaCulo!J4/100) + IF(Punteggio!G4=1,(FantaCulo!L4/100)-1, 0) - IF(Punteggio!G4=0,(FantaCulo!K4/100), 0) -> 0 | N4: 33.33 | O4: 44.44 | P4: 22.23 | Q4: =Punteggio!I4 - (3*FantaCulo!N4/100) + IF(Punteggio!I4=1,(FantaCulo!P4/100)-1, 0) - IF(Punteggio!I4=0,(FantaCulo!O4/100), 0) -> -1.4443 | R4: 33.33 | S4: 44.44 | T4: 22.23 | U4: =Punteggio!K4 - (3*FantaCulo!R4/100) + IF(Punteggio!K4=1,(FantaCulo!T4/100)-1, 0) - IF(Punteggio!K4=0,(FantaCulo!S4/100), 0) -> 2.0001 | V4: 0 | W4: 22.22 | X4: 77.78 | Y4: =Punteggio!M4 - (3*FantaCulo!V4/100) + IF(Punteggio!M4=1,(FantaCulo!X4/100)-1, 0) - IF(Punteggio!M4=0,(FantaCulo!W4/100), 0) -> -0.2222 | Z4: 33.33 | AA4: 44.44 | AB4: 22.23 | AC4: =Punteggio!O4 - (3*FantaCulo!Z4/100) + IF(Punteggio!O4=1,(FantaCulo!AB4/100)-1, 0) - IF(Punteggio!O4=0,(FantaCulo!AA4/100), 0) -> -1.4443 | AD4: 0 | AE4: 22.22 | AF4: 77.78 | AG4: =Punteggio!Q4 - (3*FantaCulo!AD4/100) + IF(Punteggio!Q4=1,(FantaCulo!AF4/100)-1, 0) - IF(Punteggio!Q4=0,(FantaCulo!AE4/100), 0) -> 0.7778 | AH4: 88.88 | AI4: 0 | AJ4: 11.12 | AK4: =Punteggio!S4 - (3*FantaCulo!AH4/100) + IF(Punteggio!S4=1,(FantaCulo!AJ4/100)-1, 0) - IF(Punteggio!S4=0,(FantaCulo!AI4/100), 0) -> 0.3336 | AL4: 0 | AM4: 22.22 | AN4: 77.78 | AO4: =Punteggio!U4 - (3*FantaCulo!AL4/100) + IF(Punteggio!U4=1,(FantaCulo!AN4/100)-1, 0) - IF(Punteggio!U4=0,(FantaCulo!AM4/100), 0) -> 0.7778
A5: 3 | B5: 11.11 | C5: 22.22 | D5: 66.67 | E5: =Punteggio!C5 - (3*FantaCulo!B5/100) + IF(Punteggio!C5=1,(FantaCulo!D5/100)-1, 0) - IF(Punteggio!C5=0,(FantaCulo!C5/100), 0) -> -0.5555 | F5: 44.44 | G5: 22.22 | H5: 33.34 | I5: =Punteggio!E5 - (3*FantaCulo!F5/100) + IF(Punteggio!E5=1,(FantaCulo!H5/100)-1, 0) - IF(Punteggio!E5=0,(FantaCulo!G5/100), 0) -> 1.6668 | J5: 77.77 | K5: 22.23 | L5: 0 | M5: =Punteggio!G5 - (3*FantaCulo!J5/100) + IF(Punteggio!G5=1,(FantaCulo!L5/100)-1, 0) - IF(Punteggio!G5=0,(FantaCulo!K5/100), 0) -> 0.6669 | N5: 44.44 | O5: 22.22 | P5: 33.34 | Q5: =Punteggio!I5 - (3*FantaCulo!N5/100) + IF(Punteggio!I5=1,(FantaCulo!P5/100)-1, 0) - IF(Punteggio!I5=0,(FantaCulo!O5/100), 0) -> -1.5554 | R5: 77.77 | S5: 22.23 | T5: 0 | U5: =Punteggio!K5 - (3*FantaCulo!R5/100) + IF(Punteggio!K5=1,(FantaCulo!T5/100)-1, 0) - IF(Punteggio!K5=0,(FantaCulo!S5/100), 0) -> 0.6669 | V5: 44.44 | W5: 22.22 | X5: 33.34 | Y5: =Punteggio!M5 - (3*FantaCulo!V5/100) + IF(Punteggio!M5=1,(FantaCulo!X5/100)-1, 0) - IF(Punteggio!M5=0,(FantaCulo!W5/100), 0) -> 1.6668 | Z5: 11.11 | AA5: 22.22 | AB5: 66.67 | AC5: =Punteggio!O5 - (3*FantaCulo!Z5/100) + IF(Punteggio!O5=1,(FantaCulo!AB5/100)-1, 0) - IF(Punteggio!O5=0,(FantaCulo!AA5/100), 0) -> -0.5555 | AD5: 11.11 | AE5: 22.22 | AF5: 66.67 | AG5: =Punteggio!Q5 - (3*FantaCulo!AD5/100) + IF(Punteggio!Q5=1,(FantaCulo!AF5/100)-1, 0) - IF(Punteggio!Q5=0,(FantaCulo!AE5/100), 0) -> -0.5555 | AH5: 0 | AI5: 0 | AJ5: 100 | AK5: =Punteggio!S5 - (3*FantaCulo!AH5/100) + IF(Punteggio!S5=1,(FantaCulo!AJ5/100)-1, 0) - IF(Punteggio!S5=0,(FantaCulo!AI5/100), 0) -> 0 | AL5: 77.77 | AM5: 22.23 | AN5: 0 | AO5: =Punteggio!U5 - (3*FantaCulo!AL5/100) + IF(Punteggio!U5=1,(FantaCulo!AN5/100)-1, 0) - IF(Punteggio!U5=0,(FantaCulo!AM5/100), 0) -> 0.6669
A6: 4 | B6: 66.66 | C6: 33.34 | D6: 0 | E6: =Punteggio!C6 - (3*FantaCulo!B6/100) + IF(Punteggio!C6=1,(FantaCulo!D6/100)-1, 0) - IF(Punteggio!C6=0,(FantaCulo!C6/100), 0) -> 1.0002 | F6: 0 | G6: 11.11 | H6: 88.89 | I6: =Punteggio!E6 - (3*FantaCulo!F6/100) + IF(Punteggio!E6=1,(FantaCulo!H6/100)-1, 0) - IF(Punteggio!E6=0,(FantaCulo!G6/100), 0) -> -0.1111 | J6: 66.66 | K6: 33.34 | L6: 0 | M6: =Punteggio!G6 - (3*FantaCulo!J6/100) + IF(Punteggio!G6=1,(FantaCulo!L6/100)-1, 0) - IF(Punteggio!G6=0,(FantaCulo!K6/100), 0) -> 1.0002 | N6: 22.22 | O6: 33.33 | P6: 44.45 | Q6: =Punteggio!I6 - (3*FantaCulo!N6/100) + IF(Punteggio!I6=1,(FantaCulo!P6/100)-1, 0) - IF(Punteggio!I6=0,(FantaCulo!O6/100), 0) -> -0.2221 | R6: 22.22 | S6: 33.33 | T6: 44.45 | U6: =Punteggio!K6 - (3*FantaCulo!R6/100) + IF(Punteggio!K6=1,(FantaCulo!T6/100)-1, 0) - IF(Punteggio!K6=0,(FantaCulo!S6/100), 0) -> -0.9999 | V6: 0 | W6: 11.11 | X6: 88.89 | Y6: =Punteggio!M6 - (3*FantaCulo!V6/100) + IF(Punteggio!M6=1,(FantaCulo!X6/100)-1, 0) - IF(Punteggio!M6=0,(FantaCulo!W6/100), 0) -> -0.1111 | Z6: 66.66 | AA6: 33.34 | AB6: 0 | AC6: =Punteggio!O6 - (3*FantaCulo!Z6/100) + IF(Punteggio!O6=1,(FantaCulo!AB6/100)-1, 0) - IF(Punteggio!O6=0,(FantaCulo!AA6/100), 0) -> 1.0002 | AD6: 22.22 | AE6: 33.33 | AF6: 44.45 | AG6: =Punteggio!Q6 - (3*FantaCulo!AD6/100) + IF(Punteggio!Q6=1,(FantaCulo!AF6/100)-1, 0) - IF(Punteggio!Q6=0,(FantaCulo!AE6/100), 0) -> -0.2221 | AH6: 22.22 | AI6: 33.33 | AJ6: 44.45 | AK6: =Punteggio!S6 - (3*FantaCulo!AH6/100) + IF(Punteggio!S6=1,(FantaCulo!AJ6/100)-1, 0) - IF(Punteggio!S6=0,(FantaCulo!AI6/100), 0) -> -0.9999 | AL6: 66.66 | AM6: 33.34 | AN6: 0 | AO6: =Punteggio!U6 - (3*FantaCulo!AL6/100) + IF(Punteggio!U6=1,(FantaCulo!AN6/100)-1, 0) - IF(Punteggio!U6=0,(FantaCulo!AM6/100), 0) -> 1.0002
A7: 5 | B7: 0 | C7: 22.22 | D7: 77.78 | E7: =Punteggio!C7 - (3*FantaCulo!B7/100) + IF(Punteggio!C7=1,(FantaCulo!D7/100)-1, 0) - IF(Punteggio!C7=0,(FantaCulo!C7/100), 0) -> -0.2222 | F7: 33.33 | G7: 11.11 | H7: 55.56 | I7: =Punteggio!E7 - (3*FantaCulo!F7/100) + IF(Punteggio!E7=1,(FantaCulo!H7/100)-1, 0) - IF(Punteggio!E7=0,(FantaCulo!G7/100), 0) -> -1.111 | J7: 33.33 | K7: 11.11 | L7: 55.56 | M7: =Punteggio!G7 - (3*FantaCulo!J7/100) + IF(Punteggio!G7=1,(FantaCulo!L7/100)-1, 0) - IF(Punteggio!G7=0,(FantaCulo!K7/100), 0) -> 2.0001 | N7: 55.55 | O7: 11.11 | P7: 33.34 | Q7: =Punteggio!I7 - (3*FantaCulo!N7/100) + IF(Punteggio!I7=1,(FantaCulo!P7/100)-1, 0) - IF(Punteggio!I7=0,(FantaCulo!O7/100), 0) -> 1.3335 | R7: 77.77 | S7: 11.11 | T7: 11.12 | U7: =Punteggio!K7 - (3*FantaCulo!R7/100) + IF(Punteggio!K7=1,(FantaCulo!T7/100)-1, 0) - IF(Punteggio!K7=0,(FantaCulo!S7/100), 0) -> -2.4442 | V7: 77.77 | W7: 11.11 | X7: 11.12 | Y7: =Punteggio!M7 - (3*FantaCulo!V7/100) + IF(Punteggio!M7=1,(FantaCulo!X7/100)-1, 0) - IF(Punteggio!M7=0,(FantaCulo!W7/100), 0) -> 0.6669 | Z7: 100 | AA7: 0 | AB7: 0 | AC7: =Punteggio!O7 - (3*FantaCulo!Z7/100) + IF(Punteggio!O7=1,(FantaCulo!AB7/100)-1, 0) - IF(Punteggio!O7=0,(FantaCulo!AA7/100), 0) -> 0 | AD7: 0 | AE7: 22.22 | AF7: 77.78 | AG7: =Punteggio!Q7 - (3*FantaCulo!AD7/100) + IF(Punteggio!Q7=1,(FantaCulo!AF7/100)-1, 0) - IF(Punteggio!Q7=0,(FantaCulo!AE7/100), 0) -> -0.2222 | AH7: 55.55 | AI7: 11.11 | AJ7: 33.34 | AK7: =Punteggio!S7 - (3*FantaCulo!AH7/100) + IF(Punteggio!S7=1,(FantaCulo!AJ7/100)-1, 0) - IF(Punteggio!S7=0,(FantaCulo!AI7/100), 0) -> 1.3335 | AL7: 0 | AM7: 22.22 | AN7: 77.78 | AO7: =Punteggio!U7 - (3*FantaCulo!AL7/100) + IF(Punteggio!U7=1,(FantaCulo!AN7/100)-1, 0) - IF(Punteggio!U7=0,(FantaCulo!AM7/100), 0) -> -0.2222
A8: 6 | B8: 88.88 | C8: 0 | D8: 11.12 | E8: =Punteggio!C8 - (3*FantaCulo!B8/100) + IF(Punteggio!C8=1,(FantaCulo!D8/100)-1, 0) - IF(Punteggio!C8=0,(FantaCulo!C8/100), 0) -> 0.3336 | F8: 66.66 | G8: 11.11 | H8: 22.23 | I8: =Punteggio!E8 - (3*FantaCulo!F8/100) + IF(Punteggio!E8=1,(FantaCulo!H8/100)-1, 0) - IF(Punteggio!E8=0,(FantaCulo!G8/100), 0) -> 1.0002 | J8: 66.66 | K8: 11.11 | L8: 22.23 | M8: =Punteggio!G8 - (3*FantaCulo!J8/100) + IF(Punteggio!G8=1,(FantaCulo!L8/100)-1, 0) - IF(Punteggio!G8=0,(FantaCulo!K8/100), 0) -> -2.1109 | N8: 11.11 | O8: 44.44 | P8: 44.45 | Q8: =Punteggio!I8 - (3*FantaCulo!N8/100) + IF(Punteggio!I8=1,(FantaCulo!P8/100)-1, 0) - IF(Punteggio!I8=0,(FantaCulo!O8/100), 0) -> 0.1112 | R8: 11.11 | S8: 44.44 | T8: 44.45 | U8: =Punteggio!K8 - (3*FantaCulo!R8/100) + IF(Punteggio!K8=1,(FantaCulo!T8/100)-1, 0) - IF(Punteggio!K8=0,(FantaCulo!S8/100), 0) -> 2.6667 | V8: 11.11 | W8: 44.44 | X8: 44.45 | Y8: =Punteggio!M8 - (3*FantaCulo!V8/100) + IF(Punteggio!M8=1,(FantaCulo!X8/100)-1, 0) - IF(Punteggio!M8=0,(FantaCulo!W8/100), 0) -> -0.7777 | Z8: 100 | AA8: 0 | AB8: 0 | AC8: =Punteggio!O8 - (3*FantaCulo!Z8/100) + IF(Punteggio!O8=1,(FantaCulo!AB8/100)-1, 0) - IF(Punteggio!O8=0,(FantaCulo!AA8/100), 0) -> 0 | AD8: 11.11 | AE8: 44.44 | AF8: 44.45 | AG8: =Punteggio!Q8 - (3*FantaCulo!AD8/100) + IF(Punteggio!Q8=1,(FantaCulo!AF8/100)-1, 0) - IF(Punteggio!Q8=0,(FantaCulo!AE8/100), 0) -> -0.7777 | AH8: 0 | AI8: 0 | AJ8: 100 | AK8: =Punteggio!S8 - (3*FantaCulo!AH8/100) + IF(Punteggio!S8=1,(FantaCulo!AJ8/100)-1, 0) - IF(Punteggio!S8=0,(FantaCulo!AI8/100), 0) -> 0 | AL8: 11.11 | AM8: 44.44 | AN8: 44.45 | AO8: =Punteggio!U8 - (3*FantaCulo!AL8/100) + IF(Punteggio!U8=1,(FantaCulo!AN8/100)-1, 0) - IF(Punteggio!U8=0,(FantaCulo!AM8/100), 0) -> 0.1112
A9: 7 | B9: 11.11 | C9: 33.33 | D9: 55.56 | E9: =Punteggio!C9 - (3*FantaCulo!B9/100) + IF(Punteggio!C9=1,(FantaCulo!D9/100)-1, 0) - IF(Punteggio!C9=0,(FantaCulo!C9/100), 0) -> 2.6667 | F9: 55.55 | G9: 22.22 | H9: 22.23 | I9: =Punteggio!E9 - (3*FantaCulo!F9/100) + IF(Punteggio!E9=1,(FantaCulo!H9/100)-1, 0) - IF(Punteggio!E9=0,(FantaCulo!G9/100), 0) -> 1.3335 | J9: 88.88 | K9: 11.12 | L9: 0 | M9: =Punteggio!G9 - (3*FantaCulo!J9/100) + IF(Punteggio!G9=1,(FantaCulo!L9/100)-1, 0) - IF(Punteggio!G9=0,(FantaCulo!K9/100), 0) -> 0.3336 | N9: 55.55 | O9: 22.22 | P9: 22.23 | Q9: =Punteggio!I9 - (3*FantaCulo!N9/100) + IF(Punteggio!I9=1,(FantaCulo!P9/100)-1, 0) - IF(Punteggio!I9=0,(FantaCulo!O9/100), 0) -> -1.4442 | R9: 11.11 | S9: 33.33 | T9: 55.56 | U9: =Punteggio!K9 - (3*FantaCulo!R9/100) + IF(Punteggio!K9=1,(FantaCulo!T9/100)-1, 0) - IF(Punteggio!K9=0,(FantaCulo!S9/100), 0) -> -0.6666 | V9: 55.55 | W9: 22.22 | X9: 22.23 | Y9: =Punteggio!M9 - (3*FantaCulo!V9/100) + IF(Punteggio!M9=1,(FantaCulo!X9/100)-1, 0) - IF(Punteggio!M9=0,(FantaCulo!W9/100), 0) -> -1.4442 | Z9: 0 | AA9: 0 | AB9: 100 | AC9: =Punteggio!O9 - (3*FantaCulo!Z9/100) + IF(Punteggio!O9=1,(FantaCulo!AB9/100)-1, 0) - IF(Punteggio!O9=0,(FantaCulo!AA9/100), 0) -> 0 | AD9: 11.11 | AE9: 33.33 | AF9: 55.56 | AG9: =Punteggio!Q9 - (3*FantaCulo!AD9/100) + IF(Punteggio!Q9=1,(FantaCulo!AF9/100)-1, 0) - IF(Punteggio!Q9=0,(FantaCulo!AE9/100), 0) -> -0.6666 | AH9: 88.88 | AI9: 11.12 | AJ9: 0 | AK9: =Punteggio!S9 - (3*FantaCulo!AH9/100) + IF(Punteggio!S9=1,(FantaCulo!AJ9/100)-1, 0) - IF(Punteggio!S9=0,(FantaCulo!AI9/100), 0) -> 0.3336 | AL9: 11.11 | AM9: 33.33 | AN9: 55.56 | AO9: =Punteggio!U9 - (3*FantaCulo!AL9/100) + IF(Punteggio!U9=1,(FantaCulo!AN9/100)-1, 0) - IF(Punteggio!U9=0,(FantaCulo!AM9/100), 0) -> -0.6666
A10: 8 | B10: 0 | C10: 11.11 | D10: 88.89 | E10: =Punteggio!C10 - (3*FantaCulo!B10/100) + IF(Punteggio!C10=1,(FantaCulo!D10/100)-1, 0) - IF(Punteggio!C10=0,(FantaCulo!C10/100), 0) -> -0.1111 | F10: 22.22 | G10: 22.22 | H10: 55.56 | I10: =Punteggio!E10 - (3*FantaCulo!F10/100) + IF(Punteggio!E10=1,(FantaCulo!H10/100)-1, 0) - IF(Punteggio!E10=0,(FantaCulo!G10/100), 0) -> -0.8888 | J10: 55.55 | K10: 33.33 | L10: 11.12 | M10: =Punteggio!G10 - (3*FantaCulo!J10/100) + IF(Punteggio!G10=1,(FantaCulo!L10/100)-1, 0) - IF(Punteggio!G10=0,(FantaCulo!K10/100), 0) -> -1.5553 | N10: 55.55 | O10: 33.33 | P10: 11.12 | Q10: =Punteggio!I10 - (3*FantaCulo!N10/100) + IF(Punteggio!I10=1,(FantaCulo!P10/100)-1, 0) - IF(Punteggio!I10=0,(FantaCulo!O10/100), 0) -> 1.3335 | R10: 0 | S10: 0 | T10: 100 | U10: =Punteggio!K10 - (3*FantaCulo!R10/100) + IF(Punteggio!K10=1,(FantaCulo!T10/100)-1, 0) - IF(Punteggio!K10=0,(FantaCulo!S10/100), 0) -> 3 | V10: 55.55 | W10: 33.33 | X10: 11.12 | Y10: =Punteggio!M10 - (3*FantaCulo!V10/100) + IF(Punteggio!M10=1,(FantaCulo!X10/100)-1, 0) - IF(Punteggio!M10=0,(FantaCulo!W10/100), 0) -> -1.5553 | Z10: 0 | AA10: 11.11 | AB10: 88.89 | AC10: =Punteggio!O10 - (3*FantaCulo!Z10/100) + IF(Punteggio!O10=1,(FantaCulo!AB10/100)-1, 0) - IF(Punteggio!O10=0,(FantaCulo!AA10/100), 0) -> -0.1111 | AD10: 22.22 | AE10: 22.22 | AF10: 55.56 | AG10: =Punteggio!Q10 - (3*FantaCulo!AD10/100) + IF(Punteggio!Q10=1,(FantaCulo!AF10/100)-1, 0) - IF(Punteggio!Q10=0,(FantaCulo!AE10/100), 0) -> -0.8888 | AH10: 22.22 | AI10: 22.22 | AJ10: 55.56 | AK10: =Punteggio!S10 - (3*FantaCulo!AH10/100) + IF(Punteggio!S10=1,(FantaCulo!AJ10/100)-1, 0) - IF(Punteggio!S10=0,(FantaCulo!AI10/100), 0) -> 2.3334 | AL10: 55.55 | AM10: 33.33 | AN10: 11.12 | AO10: =Punteggio!U10 - (3*FantaCulo!AL10/100) + IF(Punteggio!U10=1,(FantaCulo!AN10/100)-1, 0) - IF(Punteggio!U10=0,(FantaCulo!AM10/100), 0) -> 1.3335
A11: 9 | B11: 11.11 | C11: 33.33 | D11: 55.56 | E11: =Punteggio!C11 - (3*FantaCulo!B11/100) + IF(Punteggio!C11=1,(FantaCulo!D11/100)-1, 0) - IF(Punteggio!C11=0,(FantaCulo!C11/100), 0) -> -0.6666 | F11: 77.77 | G11: 0 | H11: 22.23 | I11: =Punteggio!E11 - (3*FantaCulo!F11/100) + IF(Punteggio!E11=1,(FantaCulo!H11/100)-1, 0) - IF(Punteggio!E11=0,(FantaCulo!G11/100), 0) -> 0.6669 | J11: 11.11 | K11: 33.33 | L11: 55.56 | M11: =Punteggio!G11 - (3*FantaCulo!J11/100) + IF(Punteggio!G11=1,(FantaCulo!L11/100)-1, 0) - IF(Punteggio!G11=0,(FantaCulo!K11/100), 0) -> 0.2223 | N11: 11.11 | O11: 33.33 | P11: 55.56 | Q11: =Punteggio!I11 - (3*FantaCulo!N11/100) + IF(Punteggio!I11=1,(FantaCulo!P11/100)-1, 0) - IF(Punteggio!I11=0,(FantaCulo!O11/100), 0) -> 0.2223 | R11: 55.55 | S11: 11.11 | T11: 33.34 | U11: =Punteggio!K11 - (3*FantaCulo!R11/100) + IF(Punteggio!K11=1,(FantaCulo!T11/100)-1, 0) - IF(Punteggio!K11=0,(FantaCulo!S11/100), 0) -> 1.3335 | V11: 11.11 | W11: 33.33 | X11: 55.56 | Y11: =Punteggio!M11 - (3*FantaCulo!V11/100) + IF(Punteggio!M11=1,(FantaCulo!X11/100)-1, 0) - IF(Punteggio!M11=0,(FantaCulo!W11/100), 0) -> 2.6667 | Z11: 0 | AA11: 0 | AB11: 100 | AC11: =Punteggio!O11 - (3*FantaCulo!Z11/100) + IF(Punteggio!O11=1,(FantaCulo!AB11/100)-1, 0) - IF(Punteggio!O11=0,(FantaCulo!AA11/100), 0) -> 0 | AD11: 55.55 | AE11: 11.11 | AF11: 33.34 | AG11: =Punteggio!Q11 - (3*FantaCulo!AD11/100) + IF(Punteggio!Q11=1,(FantaCulo!AF11/100)-1, 0) - IF(Punteggio!Q11=0,(FantaCulo!AE11/100), 0) -> -1.7776 | AH11: 88.88 | AI11: 11.11 | AJ11: 0 | AK11: =Punteggio!S11 - (3*FantaCulo!AH11/100) + IF(Punteggio!S11=1,(FantaCulo!AJ11/100)-1, 0) - IF(Punteggio!S11=0,(FantaCulo!AI11/100), 0) -> -2.6664 | AL11: 88.88 | AM11: 11.11 | AN11: 0 | AO11: =Punteggio!U11 - (3*FantaCulo!AL11/100) + IF(Punteggio!U11=1,(FantaCulo!AN11/100)-1, 0) - IF(Punteggio!U11=0,(FantaCulo!AM11/100), 0) -> -2.6664
A12: 10 | B12: 77.77 | C12: 11.11 | D12: 11.12 | E12: =Punteggio!C12 - (3*FantaCulo!B12/100) + IF(Punteggio!C12=1,(FantaCulo!D12/100)-1, 0) - IF(Punteggio!C12=0,(FantaCulo!C12/100), 0) -> 0.6669 | F12: 77.77 | G12: 11.11 | H12: 11.12 | I12: =Punteggio!E12 - (3*FantaCulo!F12/100) + IF(Punteggio!E12=1,(FantaCulo!H12/100)-1, 0) - IF(Punteggio!E12=0,(FantaCulo!G12/100), 0) -> -2.4442 | J12: 100 | K12: 0 | L12: 0 | M12: =Punteggio!G12 - (3*FantaCulo!J12/100) + IF(Punteggio!G12=1,(FantaCulo!L12/100)-1, 0) - IF(Punteggio!G12=0,(FantaCulo!K12/100), 0) -> 0 | N12: 0 | O12: 22.22 | P12: 77.78 | Q12: =Punteggio!I12 - (3*FantaCulo!N12/100) + IF(Punteggio!I12=1,(FantaCulo!P12/100)-1, 0) - IF(Punteggio!I12=0,(FantaCulo!O12/100), 0) -> -0.2222 | R12: 0 | S12: 22.22 | T12: 77.78 | U12: =Punteggio!K12 - (3*FantaCulo!R12/100) + IF(Punteggio!K12=1,(FantaCulo!T12/100)-1, 0) - IF(Punteggio!K12=0,(FantaCulo!S12/100), 0) -> -0.2222 | V12: 0 | W12: 22.22 | X12: 77.78 | Y12: =Punteggio!M12 - (3*FantaCulo!V12/100) + IF(Punteggio!M12=1,(FantaCulo!X12/100)-1, 0) - IF(Punteggio!M12=0,(FantaCulo!W12/100), 0) -> -0.2222 | Z12: 33.33 | AA12: 33.33 | AB12: 33.34 | AC12: =Punteggio!O12 - (3*FantaCulo!Z12/100) + IF(Punteggio!O12=1,(FantaCulo!AB12/100)-1, 0) - IF(Punteggio!O12=0,(FantaCulo!AA12/100), 0) -> 2.0001 | AD12: 33.33 | AE12: 33.33 | AF12: 33.34 | AG12: =Punteggio!Q12 - (3*FantaCulo!AD12/100) + IF(Punteggio!Q12=1,(FantaCulo!AF12/100)-1, 0) - IF(Punteggio!Q12=0,(FantaCulo!AE12/100), 0) -> -1.3332 | AH12: 33.33 | AI12: 33.33 | AJ12: 33.34 | AK12: =Punteggio!S12 - (3*FantaCulo!AH12/100) + IF(Punteggio!S12=1,(FantaCulo!AJ12/100)-1, 0) - IF(Punteggio!S12=0,(FantaCulo!AI12/100), 0) -> 2.0001 | AL12: 33.33 | AM12: 33.33 | AN12: 33.34 | AO12: =Punteggio!U12 - (3*FantaCulo!AL12/100) + IF(Punteggio!U12=1,(FantaCulo!AN12/100)-1, 0) - IF(Punteggio!U12=0,(FantaCulo!AM12/100), 0) -> 2.0001
A13: 11 | B13: 0 | C13: 0 | D13: 100 | E13: =Punteggio!C13 - (3*FantaCulo!B13/100) + IF(Punteggio!C13=1,(FantaCulo!D13/100)-1, 0) - IF(Punteggio!C13=0,(FantaCulo!C13/100), 0) -> 0 | F13: 88.88 | G13: 11.11 | H13: 0 | I13: =Punteggio!E13 - (3*FantaCulo!F13/100) + IF(Punteggio!E13=1,(FantaCulo!H13/100)-1, 0) - IF(Punteggio!E13=0,(FantaCulo!G13/100), 0) -> 0.3336 | J13: 11.11 | K13: 22.22 | L13: 66.67 | M13: =Punteggio!G13 - (3*FantaCulo!J13/100) + IF(Punteggio!G13=1,(FantaCulo!L13/100)-1, 0) - IF(Punteggio!G13=0,(FantaCulo!K13/100), 0) -> -0.5555 | N13: 44.44 | O13: 33.33 | P13: 22.23 | Q13: =Punteggio!I13 - (3*FantaCulo!N13/100) + IF(Punteggio!I13=1,(FantaCulo!P13/100)-1, 0) - IF(Punteggio!I13=0,(FantaCulo!O13/100), 0) -> -1.6665 | R13: 44.44 | S13: 33.33 | T13: 22.23 | U13: =Punteggio!K13 - (3*FantaCulo!R13/100) + IF(Punteggio!K13=1,(FantaCulo!T13/100)-1, 0) - IF(Punteggio!K13=0,(FantaCulo!S13/100), 0) -> 1.6668 | V13: 11.11 | W13: 22.22 | X13: 66.67 | Y13: =Punteggio!M13 - (3*FantaCulo!V13/100) + IF(Punteggio!M13=1,(FantaCulo!X13/100)-1, 0) - IF(Punteggio!M13=0,(FantaCulo!W13/100), 0) -> -0.5555 | Z13: 44.44 | AA13: 33.33 | AB13: 22.23 | AC13: =Punteggio!O13 - (3*FantaCulo!Z13/100) + IF(Punteggio!O13=1,(FantaCulo!AB13/100)-1, 0) - IF(Punteggio!O13=0,(FantaCulo!AA13/100), 0) -> 1.6668 | AD13: 44.44 | AE13: 33.33 | AF13: 22.23 | AG13: =Punteggio!Q13 - (3*FantaCulo!AD13/100) + IF(Punteggio!Q13=1,(FantaCulo!AF13/100)-1, 0) - IF(Punteggio!Q13=0,(FantaCulo!AE13/100), 0) -> 1.6668 | AH13: 88.88 | AI13: 11.11 | AJ13: 0 | AK13: =Punteggio!S13 - (3*FantaCulo!AH13/100) + IF(Punteggio!S13=1,(FantaCulo!AJ13/100)-1, 0) - IF(Punteggio!S13=0,(FantaCulo!AI13/100), 0) -> 0.3336 | AL13: 11.11 | AM13: 22.22 | AN13: 66.67 | AO13: =Punteggio!U13 - (3*FantaCulo!AL13/100) + IF(Punteggio!U13=1,(FantaCulo!AN13/100)-1, 0) - IF(Punteggio!U13=0,(FantaCulo!AM13/100), 0) -> -0.5555
A14: 12 | B14: 22.22 | C14: 22.22 | D14: 55.56 | E14: =Punteggio!C14 - (3*FantaCulo!B14/100) + IF(Punteggio!C14=1,(FantaCulo!D14/100)-1, 0) - IF(Punteggio!C14=0,(FantaCulo!C14/100), 0) -> 2.3334 | F14: 55.55 | G14: 33.33 | H14: 11.12 | I14: =Punteggio!E14 - (3*FantaCulo!F14/100) + IF(Punteggio!E14=1,(FantaCulo!H14/100)-1, 0) - IF(Punteggio!E14=0,(FantaCulo!G14/100), 0) -> -1.5553 | J14: 55.55 | K14: 33.33 | L14: 11.12 | M14: =Punteggio!G14 - (3*FantaCulo!J14/100) + IF(Punteggio!G14=1,(FantaCulo!L14/100)-1, 0) - IF(Punteggio!G14=0,(FantaCulo!K14/100), 0) -> 1.3335 | N14: 0 | O14: 11.11 | P14: 88.89 | Q14: =Punteggio!I14 - (3*FantaCulo!N14/100) + IF(Punteggio!I14=1,(FantaCulo!P14/100)-1, 0) - IF(Punteggio!I14=0,(FantaCulo!O14/100), 0) -> -0.1111 | R14: 100 | S14: 0 | T14: 0 | U14: =Punteggio!K14 - (3*FantaCulo!R14/100) + IF(Punteggio!K14=1,(FantaCulo!T14/100)-1, 0) - IF(Punteggio!K14=0,(FantaCulo!S14/100), 0) -> 0 | V14: 22.22 | W14: 22.22 | X14: 55.56 | Y14: =Punteggio!M14 - (3*FantaCulo!V14/100) + IF(Punteggio!M14=1,(FantaCulo!X14/100)-1, 0) - IF(Punteggio!M14=0,(FantaCulo!W14/100), 0) -> -0.8888 | Z14: 55.55 | AA14: 33.33 | AB14: 11.12 | AC14: =Punteggio!O14 - (3*FantaCulo!Z14/100) + IF(Punteggio!O14=1,(FantaCulo!AB14/100)-1, 0) - IF(Punteggio!O14=0,(FantaCulo!AA14/100), 0) -> -1.5553 | AD14: 55.55 | AE14: 33.33 | AF14: 11.12 | AG14: =Punteggio!Q14 - (3*FantaCulo!AD14/100) + IF(Punteggio!Q14=1,(FantaCulo!AF14/100)-1, 0) - IF(Punteggio!Q14=0,(FantaCulo!AE14/100), 0) -> 1.3335 | AH14: 22.22 | AI14: 22.22 | AJ14: 55.56 | AK14: =Punteggio!S14 - (3*FantaCulo!AH14/100) + IF(Punteggio!S14=1,(FantaCulo!AJ14/100)-1, 0) - IF(Punteggio!S14=0,(FantaCulo!AI14/100), 0) -> -0.8888 | AL14: 0 | AM14: 11.11 | AN14: 88.89 | AO14: =Punteggio!U14 - (3*FantaCulo!AL14/100) + IF(Punteggio!U14=1,(FantaCulo!AN14/100)-1, 0) - IF(Punteggio!U14=0,(FantaCulo!AM14/100), 0) -> -0.1111
... A37: 35 | B37: 77.77 | C37: 22.23 | D37: 0 | E37: =Punteggio!C37 - (3*FantaCulo!B37/100) + IF(Punteggio!C37=1,(FantaCulo!D37/100)-1, 0) - IF(Punteggio!C37=0,(FantaCulo!C37/100), 0) -> 0.6669 | F37: 33.33 | G37: 0 | H37: 66.67 | I37: =Punteggio!E37 - (3*FantaCulo!F37/100) + IF(Punteggio!E37=1,(FantaCulo!H37/100)-1, 0) - IF(Punteggio!E37=0,(FantaCulo!G37/100), 0) -> 2.0001 | J37: 0 | K37: 22.22 | L37: 77.78 | M37: =Punteggio!G37 - (3*FantaCulo!J37/100) + IF(Punteggio!G37=1,(FantaCulo!L37/100)-1, 0) - IF(Punteggio!G37=0,(FantaCulo!K37/100), 0) -> 0.7778 | N37: 0 | O37: 22.22 | P37: 77.78 | Q37: =Punteggio!I37 - (3*FantaCulo!N37/100) + IF(Punteggio!I37=1,(FantaCulo!P37/100)-1, 0) - IF(Punteggio!I37=0,(FantaCulo!O37/100), 0) -> -0.2222 | R37: 77.77 | S37: 22.23 | T37: 0 | U37: =Punteggio!K37 - (3*FantaCulo!R37/100) + IF(Punteggio!K37=1,(FantaCulo!T37/100)-1, 0) - IF(Punteggio!K37=0,(FantaCulo!S37/100), 0) -> -2.3331 | V37: 0 | W37: 22.22 | X37: 77.78 | Y37: =Punteggio!M37 - (3*FantaCulo!V37/100) + IF(Punteggio!M37=1,(FantaCulo!X37/100)-1, 0) - IF(Punteggio!M37=0,(FantaCulo!W37/100), 0) -> 0.7778 | Z37: 44.44 | AA37: 22.22 | AB37: 33.34 | AC37: =Punteggio!O37 - (3*FantaCulo!Z37/100) + IF(Punteggio!O37=1,(FantaCulo!AB37/100)-1, 0) - IF(Punteggio!O37=0,(FantaCulo!AA37/100), 0) -> -0.9998 | AD37: 77.77 | AE37: 22.23 | AF37: 0 | AG37: =Punteggio!Q37 - (3*FantaCulo!AD37/100) + IF(Punteggio!Q37=1,(FantaCulo!AF37/100)-1, 0) - IF(Punteggio!Q37=0,(FantaCulo!AE37/100), 0) -> -2.3331 | AH37: 44.44 | AI37: 22.22 | AJ37: 33.34 | AK37: =Punteggio!S37 - (3*FantaCulo!AH37/100) + IF(Punteggio!S37=1,(FantaCulo!AJ37/100)-1, 0) - IF(Punteggio!S37=0,(FantaCulo!AI37/100), 0) -> -1.5554 | AL37: 44.44 | AM37: 22.22 | AN37: 33.34 | AO37: =Punteggio!U37 - (3*FantaCulo!AL37/100) + IF(Punteggio!U37=1,(FantaCulo!AN37/100)-1, 0) - IF(Punteggio!U37=0,(FantaCulo!AM37/100), 0) -> -0.9998
A38: 36
A40: ∑ | B40: =SUM(E3:E38) -> 11.7817 | F40: =SUM(I3:I38) -> 12.1158 | J40: =SUM(M3:M38) -> 0.8936 | N40: =SUM(Q3:Q38) -> -6.9961 | R40: =SUM(U3:U38) -> -2.1067 | V40: =SUM(Y3:Y38) -> -4.5518 | Z40: =SUM(AC3:AC38) -> 0.115 | AD40: =SUM(AG3:AG38) -> -6.8854 | AH40: =SUM(AK3:AK38) -> -2.1073 | AL40: =SUM(AO3:AO38) -> 9.4487
B41: =B40 -> 11.7817 | F41: =F40 -> 12.1158 | J41: =J40 -> 0.8936 | N41: =N40 -> -6.9961 | R41: =R40 -> -2.1067 | V41: =V40 -> -4.5518 | Z41: =Z40 -> 0.115 | AD41: =AD40 -> -6.8854 | AH41: =AH40 -> -2.1073 | AL41: =AL40 -> 9.4487

Sheet Punteggio
A1: Giornata | B1: STRAW DOGS | D1: DELU TEAM | F1: TROFIE 'NFOIATE | H1: MAMBO FC | J1: MANZOTEAM | L1: MOJITO FC | N1: RCD SUERTE | P1: PATATINAIKOS | R1: SAMPMANIA | T1: SPACCA CFC
B2: Fantapunti | C2: Punti | D2: Fantapunti | E2: Punti | F2: Fantapunti | G2: Punti | H2: Fantapunti | I2: Punti | J2: Fantapunti | K2: Punti | L2: Fantapunti | M2: Punti | N2: Fantapunti | O2: Punti | P2: Fantapunti | Q2: Punti | R2: Fantapunti | S2: Punti | T2: Fantapunti | U2: Punti
A3: 1 | B3: 81.5 | C3: 3 | D3: 68.5 | E3: 1 | F3: 69.5 | G3: 1 | H3: 80 | I3: 3 | J3: 68.5 | K3: 0 | L3: 76.5 | M3: 0 | N3: 61 | O3: 0 | P3: 62 | Q3: 0 | R3: 91 | S3: 3 | T3: 78.5 | U3: 3
A4: 2 | B4: 72.5 | C4: 1 | D4: 73.5 | E4: 1 | F4: 85.5 | G4: 3 | H4: 72.5 | I4: 0 | J4: 75 | K4: 3 | L4: 70 | M4: 0 | N4: 75 | O4: 0 | P4: 68 | Q4: 1 | R4: 81 | S4: 3 | T4: 70.5 | U4: 1
A5: 3 | B5: 67.5 | C5: 0 | D5: 76 | E5: 3 | F5: 83 | G5: 3 | H5: 72.5 | I5: 0 | J5: 79 | K5: 3 | L5: 73 | M5: 3 | N5: 69 | O5: 0 | P5: 67 | Q5: 0 | R5: 62 | S5: 0 | T5: 79.5 | U5: 3
A6: 4 | B6: 73.5 | C6: 3 | D6: 64.5 | E6: 0 | F6: 73.5 | G6: 3 | H6: 70.5 | I6: 1 | J6: 66 | K6: 0 | L6: 64 | M6: 0 | N6: 72.5 | O6: 3 | P6: 67 | Q6: 1 | R6: 70.5 | S6: 0 | T6: 77.5 | U6: 3
A7: 5 | B7: 65.5 | C7: 0 | D7: 69.5 | E7: 0 | F7: 71 | G7: 3 | H7: 76 | I7: 3 | J7: 82 | K7: 0 | L7: 78.5 | M7: 3 | N7: 85 | O7: 3 | P7: 62.5 | Q7: 0 | R7: 73.5 | S7: 3 | T7: 65 | U7: 0
A8: 6 | B8: 78.5 | C8: 3 | D8: 75 | E8: 3 | F8: 72.5 | G8: 0 | H8: 67 | I8: 1 | J8: 67.5 | K8: 3 | L8: 69.5 | M8: 0 | N8: 88.5 | O8: 3 | P8: 68 | Q8: 0 | R8: 63 | S8: 0 | T8: 71.5 | U8: 1
A9: 7 | B9: 68 | C9: 3 | D9: 74.5 | E9: 3 | F9: 83 | G9: 3 | H9: 77 | I9: 1 | J9: 68.5 | K9: 0 | L9: 73 | M9: 1 | N9: 63.5 | O9: 0 | P9: 67 | Q9: 0 | R9: 79 | S9: 3 | T9: 68 | U9: 0
A10: 8 | B10: 60 | C10: 0 | D10: 71 | E10: 0 | F10: 72.5 | G10: 1 | H10: 76.5 | I10: 3 | J10: 79 | K10: 3 | L10: 75.5 | M10: 1 | N10: 63 | O10: 0 | P10: 67.5 | Q10: 0 | R10: 66 | S10: 3 | T10: 75.5 | U10: 3
A11: 9 | B11: 71.5 | C11: 0 | D11: 82 | E11: 3 | F11: 66 | G11: 1 | H11: 67 | I11: 1 | J11: 76 | K11: 3 | L11: 71.5 | M11: 3 | N11: 62.5 | O11: 0 | P11: 75 | Q11: 0 | R11: 84.5 | S11: 1 | T11: 85.5 | U11: 1
A12: 10 | B12: 81 | C12: 3 | D12: 82 | E12: 0 | F12: 87 | G12: 3 | H12: 65 | I12: 0 | J12: 65.5 | K12: 0 | L12: 65 | M12: 0 | N12: 74.5 | O12: 3 | P12: 74 | Q12: 0 | R12: 75.5 | S12: 3 | T12: 75 | U12: 3
A13: 11 | B13: 59 | C13: 0 | D13: 78.5 | E13: 3 | F13: 69 | G13: 0 | H13: 75 | I13: 0 | J13: 74.5 | K13: 3 | L13: 70 | M13: 0 | N13: 74 | O13: 3 | P13: 72 | Q13: 3 | R13: 80.5 | S13: 3 | T13: 67.5 | U13: 0
A14: 12 | B14: 67.5 | C14: 3 | D14: 72 | E14: 1 | F14: 74 | G14: 3 | H14: 60 | I14: 0 | J14: 78.5 | K14: 3 | L14: 68 | M14: 0 | N14: 72 | O14: 1 | P14: 77 | Q14: 3 | R14: 68 | S14: 0 | T14: 65 | U14: 0
... A37: 35 | B37: 80 | C37: 3 | D37: 71 | E37: 3 | F37: 61.5 | G37: 1 | H37: 53.5 | I37: 0 | J37: 83.5 | K37: 1 | L37: 65.5 | M37: 1 | N37: 72.5 | O37: 1 | P37: 78 | Q37: 1 | R37: 76 | S37: 0 | T37: 74 | U37: 1
A38: 36
A39: Totale | B39: =SUM(B3:B38) -> 2523 | C39: =SUM(C3:C38) -> 52 | D39: =SUM(D3:D38) -> 2613.5 | E39: =SUM(E3:E38) -> 65 | F39: =SUM(F3:F38) -> 2613 | G39: =SUM(G3:G38) -> 56 | H39: =SUM(H3:H38) -> 2504 | I39: =SUM(I3:I38) -> 35 | ... U39: =SUM(U3:U38) -> 60
A40: Punteggio Max | B40: =MAX(B3:B38) -> 83 | D40: =MAX(D3:D38) -> 86.5 | F40: =MAX(F3:F38) -> 87 | H40: =MAX(H3:H38) -> 88 | J40: =MAX(J3:J38) -> 89 | L40: =MAX(L3:L38) -> 91.5 | N40: =MAX(N3:N38) -> 88.5 | P40: =MAX(P3:P38) -> 94 | R40: =MAX(R3:R38) -> 91 | T40: =MAX(T3:T38) -> 90.5
A41: Media | B41: =AVERAGE(B3:B38) -> 72.085714 | C41: =AVERAGE(C3:C38) -> 1.4857143 | D41: =AVERAGE(D3:D38) -> 74.671429 | E41: =AVERAGE(E3:E38) -> 1.8571429 | F41: =AVERAGE(F3:F38) -> 74.657143 | G41: =AVERAGE(G3:G38) -> 1.6 | H41: =AVERAGE(H3:H38) -> 71.542857 | I41: =AVERAGE(I3:I38) -> 1 | ... U41: =AVERAGE(U3:U38) -> 1.7142857
A43: Differenza Reti | B43: =B51-C51 -> -1 | D43: =D51-E51 -> 10 | F43: =F51-G51 -> 12 | H43: =H51-I51 -> -9 | J43: =J51-K51 -> 7 | L43: =L51-M51 -> -14 | N43: =N51-O51 -> 2 | P43: =P51-Q51 -> -13 | R43: =R51-S51 -> -6 | T43: =T51-U51 -> 12
A45: Handicap | B45: =COUNTIF(B3:B38, 65.5) + COUNTIF(B3:B38, 71.5) + COUNTIF(B3:B38, 77.5) + COUNTIF(B3:B38, 83.5) + COUNTIF(B3:B38, 89.5) + COUNTIF(B3:B38, 95.5) -> 4 | D45: =COUNTIF(D3:D38, 65.5) + COUNTIF(D3:D38, 71.5) + COUNTIF(D3:D38, 77.5) + COUNTIF(D3:D38, 83.5) + COUNTIF(D3:D38, 89.5) + COUNTIF(D3:D38, 95.5) -> 0 | F45: =COUNTIF(F3:F38, 65.5) + COUNTIF(F3:F38, 71.5) + COUNTIF(F3:F38, 77.5) + COUNTIF(F3:F38, 83.5) + COUNTIF(F3:F38, 89.5) + COUNTIF(F3:F38, 95.5) -> 0 | H45: =COUNTIF(H3:H38, 65.5) + COUNTIF(H3:H38, 71.5) + COUNTIF(H3:H38, 77.5) + COUNTIF(H3:H38, 83.5) + COUNTIF(H3:H38, 89.5) + COUNTIF(H3:H38, 95.5) -> 1 | J45: =COUNTIF(J3:J38, 65.5) + COUNTIF(J3:J38, 71.5) + COUNTIF(J3:J38, 77.5) + COUNTIF(J3:J38, 83.5) + COUNTIF(J3:J38, 89.5) + COUNTIF(J3:J38, 95.5) -> 3 | L45: =COUNTIF(L3:L38, 65.5) + COUNTIF(L3:L38, 71.5) + COUNTIF(L3:L38, 77.5) + COUNTIF(L3:L38, 83.5) + COUNTIF(L3:L38, 89.5) + COUNTIF(L3:L38, 95.5) -> 3 | N45: =COUNTIF(N3:N38, 65.5) + COUNTIF(N3:N38, 71.5) + COUNTIF(N3:N38, 77.5) + COUNTIF(N3:N38, 83.5) + COUNTIF(N3:N38, 89.5) + COUNTIF(N3:N38, 95.5) -> 3 | P45: =COUNTIF(P3:P38, 65.5) + COUNTIF(P3:P38, 71.5) + COUNTIF(P3:P38, 77.5) + COUNTIF(P3:P38, 83.5) + COUNTIF(P3:P38, 89.5) + COUNTIF(P3:P38, 95.5) -> 3 | R45: =COUNTIF(R3:R38, 65.5) + COUNTIF(R3:R38, 71.5) + COUNTIF(R3:R38, 77.5) + COUNTIF(R3:R38, 83.5) + COUNTIF(R3:R38, 89.5) + COUNTIF(R3:R38, 95.5) -> 0 | T45: =COUNTIF(T3:T38, 65.5) + COUNTIF(T3:T38, 71.5) + COUNTIF(T3:T38, 77.5) + COUNTIF(T3:T38, 83.5) + COUNTIF(T3:T38, 89.5) + COUNTIF(T3:T38, 95.5) -> 3
A46: Punti Persi | B46: 3 | H46: 2 | J46: 1 | L46: 2 | N46: 5 | P46: 2 | T46: 2
A48: Cifra Tonda | B48: =COUNTIF(B3:B38, 66) + COUNTIF(B3:B38, 72) + COUNTIF(B3:B38, 78) + COUNTIF(B3:B38, 84) + COUNTIF(B3:B38, 90) + COUNTIF(B3:B38, 96) -> 2 | D48: =COUNTIF(D3:D38, 66) + COUNTIF(D3:D38, 72) + COUNTIF(D3:D38, 78) + COUNTIF(D3:D38, 84) + COUNTIF(D3:D38, 90) + COUNTIF(D3:D38, 96) -> 2 | F48: =COUNTIF(F3:F38, 66) + COUNTIF(F3:F38, 72) + COUNTIF(F3:F38, 78) + COUNTIF(F3:F38, 84) + COUNTIF(F3:F38, 90) + COUNTIF(F3:F38, 96) -> 3 | H48: =COUNTIF(H3:H38, 66) + COUNTIF(H3:H38, 72) + COUNTIF(H3:H38, 78) + COUNTIF(H3:H38, 84) + COUNTIF(H3:H38, 90) + COUNTIF(H3:H38, 96) -> 1 | J48: =COUNTIF(J3:J38, 66) + COUNTIF(J3:J38, 72) + COUNTIF(J3:J38, 78) + COUNTIF(J3:J38, 84) + COUNTIF(J3:J38, 90) + COUNTIF(J3:J38, 96) -> 3 | L48: =COUNTIF(L3:L38, 66) + COUNTIF(L3:L38, 72) + COUNTIF(L3:L38, 78) + COUNTIF(L3:L38, 84) + COUNTIF(L3:L38, 90) + COUNTIF(L3:L38, 96) -> 2 | N48: =COUNTIF(N3:N38, 66) + COUNTIF(N3:N38, 72) + COUNTIF(N3:N38, 78) + COUNTIF(N3:N38, 84) + COUNTIF(N3:N38, 90) + COUNTIF(N3:N38, 96) -> 3 | P48: =COUNTIF(P3:P38, 66) + COUNTIF(P3:P38, 72) + COUNTIF(P3:P38, 78) + COUNTIF(P3:P38, 84) + COUNTIF(P3:P38, 90) + COUNTIF(P3:P38, 96) -> 3 | R48: =COUNTIF(R3:R38, 66) + COUNTIF(R3:R38, 72) + COUNTIF(R3:R38, 78) + COUNTIF(R3:R38, 84) + COUNTIF(R3:R38, 90) + COUNTIF(R3:R38, 96) -> 3 | T48: =COUNTIF(T3:T38, 66) + COUNTIF(T3:T38, 72) + COUNTIF(T3:T38, 78) + COUNTIF(T3:T38, 84) + COUNTIF(T3:T38, 90) + COUNTIF(T3:T38, 96) -> 3
A49: Punti Guadagnati | B49: 2 | D49: 1 | F49: 2 | H49: 0 | J49: 1 | L49: 0 | N49: 3 | P49: 5 | R49: 2 | T49: 1
A51: Gol fatti/ subiti | B51: 56 | C51: 57 | D51: 69 | E51: 59 | F51: 70 | G51: 58 | H51: 54 | I51: 63 | J51: 80 | K51: 73 | L51: 56 | M51: 70 | N51: 67 | O51: 65 | P51: 64 | Q51: 77 | R51: 62 | S51: 68 | T51: 70 | U51: 58
A53: Vittoria | B53: =COUNTIF(C3:C38,3) -> 15 | C53: =B53/'RAW DATA andamento'!$B$57 -> 0.42857143 | D53: =COUNTIF(E3:E38,3) -> 20 | E53: =D53/'RAW DATA andamento'!$B$57 -> 0.57142857 | F53: =COUNTIF(G3:G38,3) -> 15 | G53: =F53/'RAW DATA andamento'!$B$57 -> 0.42857143 | H53: =COUNTIF(I3:I38,3) -> 9 | I53: =H53/'RAW DATA andamento'!$B$57 -> 0.25714286 | J53: =COUNTIF(K3:K38,3) -> 17 | K53: =J53/'RAW DATA andamento'!$B$57 -> 0.48571429 | L53: =COUNTIF(M3:M38,3) -> 10 | M53: =L53/'RAW DATA andamento'!$B$57 -> 0.28571429 | N53: =COUNTIF(O3:O38,3) -> 14 | O53: =N53/'RAW DATA andamento'!$B$57 -> 0.4 | P53: =COUNTIF(Q3:Q38,3) -> 11 | Q53: =P53/'RAW DATA andamento'!$B$57 -> 0.31428571 | R53: =COUNTIF(S3:S38,3) -> 13 | S53: =R53/'RAW DATA andamento'!$B$57 -> 0.37142857 | T53: =COUNTIF(U3:U38,3) -> 17 | U53: =T53/'RAW DATA andamento'!$B$57 -> 0.48571429
A54: Pareggio | B54: =COUNTIF(C3:C38,1) -> 7 | C54: =B54/'RAW DATA andamento'!$B$57 -> 0.2 | D54: =COUNTIF(E3:E38,1) -> 5 | E54: =D54/'RAW DATA andamento'!$B$57 -> 0.14285714 | F54: =COUNTIF(G3:G38,1) -> 11 | G54: =F54/'RAW DATA andamento'!$B$57 -> 0.31428571 | H54: =COUNTIF(I3:I38,1) -> 8 | I54: =H54/'RAW DATA andamento'!$B$57 -> 0.22857143 | J54: =COUNTIF(K3:K38,1) -> 5 | K54: =J54/'RAW DATA andamento'!$B$57 -> 0.14285714 | L54: =COUNTIF(M3:M38,1) -> 5 | M54: =L54/'RAW DATA andamento'!$B$57 -> 0.14285714 | N54: =COUNTIF(O3:O38,1) -> 8 | O54: =N54/'RAW DATA andamento'!$B$57 -> 0.22857143 | P54: =COUNTIF(Q3:Q38,1) -> 6 | Q54: =P54/'RAW DATA andamento'!$B$57 -> 0.17142857 | R54: =COUNTIF(S3:S38,1) -> 4 | S54: =R54/'RAW DATA andamento'!$B$57 -> 0.11428571 | T54: =COUNTIF(U3:U38,1) -> 9 | U54: =T54/'RAW DATA andamento'!$B$57 -> 0.25714286
A55: Sconfitta | B55: =COUNTIF(C3:C38,0) -> 13 | C55: =B55/'RAW DATA andamento'!$B$57 -> 0.37142857 | D55: =COUNTIF(E3:E38,0) -> 10 | E55: =D55/'RAW DATA andamento'!$B$57 -> 0.28571429 | F55: =COUNTIF(G3:G38,0) -> 9 | G55: =F55/'RAW DATA andamento'!$B$57 -> 0.25714286 | H55: =COUNTIF(I3:I38,0) -> 18 | I55: =H55/'RAW DATA andamento'!$B$57 -> 0.51428571 | J55: =COUNTIF(K3:K38,0) -> 13 | K55: =J55/'RAW DATA andamento'!$B$57 -> 0.37142857 | L55: =COUNTIF(M3:M38,0) -> 20 | M55: =L55/'RAW DATA andamento'!$B$57 -> 0.57142857 | N55: =COUNTIF(O3:O38,0) -> 13 | O55: =N55/'RAW DATA andamento'!$B$57 -> 0.37142857 | P55: =COUNTIF(Q3:Q38,0) -> 18 | Q55: =P55/'RAW DATA andamento'!$B$57 -> 0.51428571 | R55: =COUNTIF(S3:S38,0) -> 18 | S55: =R55/'RAW DATA andamento'!$B$57 -> 0.51428571 | T55: =COUNTIF(U3:U38,0) -> 9 | U55: =T55/'RAW DATA andamento'!$B$57 -> 0.25714286
A57: Fascia 0 Gol | B57: =COUNTIF(B3:B38,"<66") -> 5 | C57: =B57/'RAW DATA andamento'!$B$57 -> 0.14285714 | D57: =COUNTIF(D3:D38,"<66") -> 5 | E57: =D57/'RAW DATA andamento'!$B$57 -> 0.14285714 | F57: =COUNTIF(F3:F38,"<66") -> 2 | G57: =F57/'RAW DATA andamento'!$B$57 -> 0.057142857 | H57: =COUNTIF(H3:H38,"<66") -> 7 | I57: =H57/'RAW DATA andamento'!$B$57 -> 0.2 | J57: =COUNTIF(J3:J38,"<66") -> 1 | K57: =J57/'RAW DATA andamento'!$B$57 -> 0.028571429 | L57: =COUNTIF(L3:L38,"<66") -> 5 | M57: =L57/'RAW DATA andamento'!$B$57 -> 0.14285714 | N57: =COUNTIF(N3:N38,"<66") -> 7 | O57: =N57/'RAW DATA andamento'!$B$57 -> 0.2 | P57: =COUNTIF(P3:P38,"<66") -> 5 | Q57: =P57/'RAW DATA andamento'!$B$57 -> 0.14285714 | R57: =COUNTIF(R3:R38,"<66") -> 4 | S57: =R57/'RAW DATA andamento'!$B$57 -> 0.11428571 | T57: =COUNTIF(T3:T38,"<66") -> 2 | U57: =T57/'RAW DATA andamento'!$B$57 -> 0.057142857
A58: Fascia 1 Gol | B58: =COUNTIFS(B3:B38,"> 66", B3:B38,"< 72")+COUNTIF(B3:B38,"=66") -> 13 | C58: =B58/'RAW DATA andamento'!$B$57 -> 0.37142857 | D58: =COUNTIFS(D3:D38,"> 66", D3:D38,"< 72")+COUNTIF(D3:D38,"=66") -> 6 | E58: =D58/'RAW DATA andamento'!$B$57 -> 0.17142857 | F58: =COUNTIFS(F3:F38,"> 66", F3:F38,"< 72")+COUNTIF(F3:F38,"=66") -> 10 | G58: =F58/'RAW DATA andamento'!$B$57 -> 0.28571429 | H58: =COUNTIFS(H3:H38,"> 66", H3:H38,"< 72")+COUNTIF(H3:H38,"=66") -> 9 | I58: =H58/'RAW DATA andamento'!$B$57 -> 0.25714286 | J58: =COUNTIFS(J3:J38,"> 66", J3:J38,"< 72")+COUNTIF(J3:J38,"=66") -> 9 | K58: =J58/'RAW DATA andamento'!$B$57 -> 0.25714286 | L58: =COUNTIFS(L3:L38,"> 66", L3:L38,"< 72")+COUNTIF(L3:L38,"=66") -> 11 | M58: =L58/'RAW DATA andamento'!$B$57 -> 0.31428571 | N58: =COUNTIFS(N3:N38,"> 66", N3:N38,"< 72")+COUNTIF(N3:N38,"=66") -> 4 | O58: =N58/'RAW DATA andamento'!$B$57 -> 0.11428571 | P58: =COUNTIFS(P3:P38,"> 66", P3:P38,"< 72")+COUNTIF(P3:P38,"=66") -> 11 | Q58: =P58/'RAW DATA andamento'!$B$57 -> 0.31428571 | R58: =COUNTIFS(R3:R38,"> 66", R3:R38,"< 72")+COUNTIF(R3:R38,"=66") -> 13 | S58: =R58/'RAW DATA andamento'!$B$57 -> 0.37142857 | T58: =COUNTIFS(T3:T38,"> 66", T3:T38,"< 72")+COUNTIF(T3:T38,"=66") -> 10 | U58: =T58/'RAW DATA andamento'!$B$57 -> 0.28571429
A59: Fascia 2 Gol | B59: =COUNTIFS(B3:B38,"> 72", B3:B38,"< 78")+COUNTIF(B3:B38,"=72") -> 8 | C59: =B59/'RAW DATA andamento'!$B$57 -> 0.22857143 | D59: =COUNTIFS(D3:D38,"> 72", D3:D38,"< 78")+COUNTIF(D3:D38,"=72") -> 11 | E59: =D59/'RAW DATA andamento'!$B$57 -> 0.31428571 | F59: =COUNTIFS(F3:F38,"> 72", F3:F38,"< 78")+COUNTIF(F3:F38,"=72") -> 12 | G59: =F59/'RAW DATA andamento'!$B$57 -> 0.34285714 | H59: =COUNTIFS(H3:H38,"> 72", H3:H38,"< 78")+COUNTIF(H3:H38,"=72") -> 13 | I59: =H59/'RAW DATA andamento'!$B$57 -> 0.37142857 | J59: =COUNTIFS(J3:J38,"> 72", J3:J38,"< 78")+COUNTIF(J3:J38,"=72") -> 9 | K59: =J59/'RAW DATA andamento'!$B$57 -> 0.25714286 | L59: =COUNTIFS(L3:L38,"> 72", L3:L38,"< 78")+COUNTIF(L3:L38,"=72") -> 14 | M59: =L59/'RAW DATA andamento'!$B$57 -> 0.4 | N59: =COUNTIFS(N3:N38,"> 72", N3:N38,"< 78")+COUNTIF(N3:N38,"=72") -> 14 | O59: =N59/'RAW DATA andamento'!$B$57 -> 0.4 | P59: =COUNTIFS(P3:P38,"> 72", P3:P38,"< 78")+COUNTIF(P3:P38,"=72") -> 9 | Q59: =P59/'RAW DATA andamento'!$B$57 -> 0.25714286 | R59: =COUNTIFS(R3:R38,"> 72", R3:R38,"< 78")+COUNTIF(R3:R38,"=72") -> 10 | S59: =R59/'RAW DATA andamento'!$B$57 -> 0.28571429 | T59: =COUNTIFS(T3:T38,"> 72", T3:T38,"< 78")+COUNTIF(T3:T38,"=72") -> 14 | U59: =T59/'RAW DATA andamento'!$B$57 -> 0.4
